2025-10-19 17:07:15,230 - asyncio - ERROR - Exception in callback Client.receive_loop.<locals>.after_interrupt(<Task cancell...nt_ws.py:312>>) at /home/ar1ess/projects/crypto/.venv/lib/python3.12/site-packages/ccxt/async_support/base/ws/client.py:129
handle: <Handle Client.receive_loop.<locals>.after_interrupt(<Task cancell...nt_ws.py:312>>) at /home/ar1ess/projects/crypto/.venv/lib/python3.12/site-packages/ccxt/async_support/base/ws/client.py:129>
Traceback (most recent call last):
  File "/usr/lib/python3.12/asyncio/runners.py", line 118, in run
    return self._loop.run_until_complete(task)
           ^^^^^^^^^^^^^^^^^^^^^^^^^^^^^^^^^^^
  File "/usr/lib/python3.12/asyncio/base_events.py", line 687, in run_until_complete
    return future.result()
           ^^^^^^^^^^^^^^^
  File "/home/ar1ess/projects/crypto/brain/main.py", line 372, in main
    await analyst.start_update()
  File "/home/ar1ess/projects/crypto/brain/Core/Analyst.py", line 227, in start_update
    await self.scout.start_monitoring()
  File "/home/ar1ess/projects/crypto/brain/Core/scouts/ScoutDad.py", line 27, in start_monitoring
    await asyncio.gather(*tasks, return_exceptions=True)
asyncio.exceptions.CancelledError

During handling of the above exception, another exception occurred:

Traceback (most recent call last):
  File "/usr/lib/python3.12/asyncio/runners.py", line 194, in run
    return runner.run(main)
           ^^^^^^^^^^^^^^^^
  File "/usr/lib/python3.12/asyncio/runners.py", line 123, in run
    raise KeyboardInterrupt()
KeyboardInterrupt

During handling of the above exception, another exception occurred:

Traceback (most recent call last):
  File "/usr/lib/python3.12/asyncio/events.py", line 88, in _run
    self._context.run(self._callback, *self._args)
  File "/home/ar1ess/projects/crypto/.venv/lib/python3.12/site-packages/ccxt/async_support/base/ws/client.py", line 130, in after_interrupt
    exception = resolved.exception()
                ^^^^^^^^^^^^^^^^^^^^
  File "/home/ar1ess/projects/crypto/.venv/lib/python3.12/site-packages/aiohttp/client_ws.py", line 336, in receive
    msg = await self._reader.read()
          ^^^^^^^^^^^^^^^^^^^^^^^^^
  File "aiohttp/_websocket/reader_c.py", line 118, in read
  File "aiohttp/_websocket/reader_c.py", line 115, in aiohttp._websocket.reader_c.WebSocketDataQueue.read
asyncio.exceptions.CancelledError
2025-10-19 17:07:15,235 - asyncio - ERROR - Exception in callback Future.race.<locals>.callback(<Task cancell...tasks.py:435>>) at /home/ar1ess/projects/crypto/.venv/lib/python3.12/site-packages/ccxt/async_support/base/ws/future.py:22
handle: <Handle Future.race.<locals>.callback(<Task cancell...tasks.py:435>>) at /home/ar1ess/projects/crypto/.venv/lib/python3.12/site-packages/ccxt/async_support/base/ws/future.py:22>
Traceback (most recent call last):
  File "/usr/lib/python3.12/asyncio/runners.py", line 118, in run
    return self._loop.run_until_complete(task)
           ^^^^^^^^^^^^^^^^^^^^^^^^^^^^^^^^^^^
  File "/usr/lib/python3.12/asyncio/base_events.py", line 687, in run_until_complete
    return future.result()
           ^^^^^^^^^^^^^^^
  File "/home/ar1ess/projects/crypto/brain/main.py", line 372, in main
    await analyst.start_update()
  File "/home/ar1ess/projects/crypto/brain/Core/Analyst.py", line 227, in start_update
    await self.scout.start_monitoring()
  File "/home/ar1ess/projects/crypto/brain/Core/scouts/ScoutDad.py", line 27, in start_monitoring
    await asyncio.gather(*tasks, return_exceptions=True)
asyncio.exceptions.CancelledError

During handling of the above exception, another exception occurred:

Traceback (most recent call last):
  File "/usr/lib/python3.12/asyncio/runners.py", line 194, in run
    return runner.run(main)
           ^^^^^^^^^^^^^^^^
  File "/usr/lib/python3.12/asyncio/runners.py", line 123, in run
    raise KeyboardInterrupt()
KeyboardInterrupt

During handling of the above exception, another exception occurred:

Traceback (most recent call last):
  File "/usr/lib/python3.12/asyncio/events.py", line 88, in _run
    self._context.run(self._callback, *self._args)
  File "/home/ar1ess/projects/crypto/.venv/lib/python3.12/site-packages/ccxt/async_support/base/ws/future.py", line 23, in callback
    complete, _ = done.result()
                  ^^^^^^^^^^^^^
  File "/usr/lib/python3.12/asyncio/tasks.py", line 464, in wait
    return await _wait(fs, timeout, return_when, loop)
           ^^^^^^^^^^^^^^^^^^^^^^^^^^^^^^^^^^^^^^^^^^^
  File "/usr/lib/python3.12/asyncio/tasks.py", line 550, in _wait
    await waiter
asyncio.exceptions.CancelledError
2025-10-19 17:12:52,543 - asyncio - ERROR - Exception in callback Future.race.<locals>.callback(<Task cancell...tasks.py:435>>) at /home/ar1ess/projects/crypto/.venv/lib/python3.12/site-packages/ccxt/async_support/base/ws/future.py:22
handle: <Handle Future.race.<locals>.callback(<Task cancell...tasks.py:435>>) at /home/ar1ess/projects/crypto/.venv/lib/python3.12/site-packages/ccxt/async_support/base/ws/future.py:22>
Traceback (most recent call last):
  File "/usr/lib/python3.12/asyncio/runners.py", line 118, in run
    return self._loop.run_until_complete(task)
           ^^^^^^^^^^^^^^^^^^^^^^^^^^^^^^^^^^^
  File "/usr/lib/python3.12/asyncio/base_events.py", line 687, in run_until_complete
    return future.result()
           ^^^^^^^^^^^^^^^
  File "/home/ar1ess/projects/crypto/brain/main.py", line 372, in main
    await analyst.start_update()
  File "/home/ar1ess/projects/crypto/brain/Core/Analyst.py", line 227, in start_update
    await self.scout.start_monitoring()
  File "/home/ar1ess/projects/crypto/brain/Core/scouts/ScoutDad.py", line 27, in start_monitoring
    await asyncio.gather(*tasks, return_exceptions=True)
asyncio.exceptions.CancelledError

During handling of the above exception, another exception occurred:

Traceback (most recent call last):
  File "/usr/lib/python3.12/asyncio/runners.py", line 194, in run
    return runner.run(main)
           ^^^^^^^^^^^^^^^^
  File "/usr/lib/python3.12/asyncio/runners.py", line 123, in run
    raise KeyboardInterrupt()
KeyboardInterrupt

During handling of the above exception, another exception occurred:

Traceback (most recent call last):
  File "/usr/lib/python3.12/asyncio/events.py", line 88, in _run
    self._context.run(self._callback, *self._args)
  File "/home/ar1ess/projects/crypto/.venv/lib/python3.12/site-packages/ccxt/async_support/base/ws/future.py", line 23, in callback
    complete, _ = done.result()
                  ^^^^^^^^^^^^^
  File "/usr/lib/python3.12/asyncio/tasks.py", line 464, in wait
    return await _wait(fs, timeout, return_when, loop)
           ^^^^^^^^^^^^^^^^^^^^^^^^^^^^^^^^^^^^^^^^^^^
  File "/usr/lib/python3.12/asyncio/tasks.py", line 550, in _wait
    await waiter
asyncio.exceptions.CancelledError
2025-10-19 17:12:52,549 - asyncio - ERROR - Exception in callback Client.receive_loop.<locals>.after_interrupt(<Task cancell...nt_ws.py:312>>) at /home/ar1ess/projects/crypto/.venv/lib/python3.12/site-packages/ccxt/async_support/base/ws/client.py:129
handle: <Handle Client.receive_loop.<locals>.after_interrupt(<Task cancell...nt_ws.py:312>>) at /home/ar1ess/projects/crypto/.venv/lib/python3.12/site-packages/ccxt/async_support/base/ws/client.py:129>
Traceback (most recent call last):
  File "/usr/lib/python3.12/asyncio/runners.py", line 118, in run
    return self._loop.run_until_complete(task)
           ^^^^^^^^^^^^^^^^^^^^^^^^^^^^^^^^^^^
  File "/usr/lib/python3.12/asyncio/base_events.py", line 687, in run_until_complete
    return future.result()
           ^^^^^^^^^^^^^^^
  File "/home/ar1ess/projects/crypto/brain/main.py", line 372, in main
    await analyst.start_update()
  File "/home/ar1ess/projects/crypto/brain/Core/Analyst.py", line 227, in start_update
    await self.scout.start_monitoring()
  File "/home/ar1ess/projects/crypto/brain/Core/scouts/ScoutDad.py", line 27, in start_monitoring
    await asyncio.gather(*tasks, return_exceptions=True)
asyncio.exceptions.CancelledError

During handling of the above exception, another exception occurred:

Traceback (most recent call last):
  File "/usr/lib/python3.12/asyncio/runners.py", line 194, in run
    return runner.run(main)
           ^^^^^^^^^^^^^^^^
  File "/usr/lib/python3.12/asyncio/runners.py", line 123, in run
    raise KeyboardInterrupt()
KeyboardInterrupt

During handling of the above exception, another exception occurred:

Traceback (most recent call last):
  File "/usr/lib/python3.12/asyncio/events.py", line 88, in _run
    self._context.run(self._callback, *self._args)
  File "/home/ar1ess/projects/crypto/.venv/lib/python3.12/site-packages/ccxt/async_support/base/ws/client.py", line 130, in after_interrupt
    exception = resolved.exception()
                ^^^^^^^^^^^^^^^^^^^^
  File "/home/ar1ess/projects/crypto/.venv/lib/python3.12/site-packages/aiohttp/client_ws.py", line 336, in receive
    msg = await self._reader.read()
          ^^^^^^^^^^^^^^^^^^^^^^^^^
  File "aiohttp/_websocket/reader_c.py", line 118, in read
  File "aiohttp/_websocket/reader_c.py", line 115, in aiohttp._websocket.reader_c.WebSocketDataQueue.read
asyncio.exceptions.CancelledError
2025-10-19 17:12:52,550 - asyncio - ERROR - Exception in callback Client.receive_loop.<locals>.after_interrupt(<Task cancell...nt_ws.py:312>>) at /home/ar1ess/projects/crypto/.venv/lib/python3.12/site-packages/ccxt/async_support/base/ws/client.py:129
handle: <Handle Client.receive_loop.<locals>.after_interrupt(<Task cancell...nt_ws.py:312>>) at /home/ar1ess/projects/crypto/.venv/lib/python3.12/site-packages/ccxt/async_support/base/ws/client.py:129>
Traceback (most recent call last):
  File "/usr/lib/python3.12/asyncio/runners.py", line 118, in run
    return self._loop.run_until_complete(task)
           ^^^^^^^^^^^^^^^^^^^^^^^^^^^^^^^^^^^
  File "/usr/lib/python3.12/asyncio/base_events.py", line 687, in run_until_complete
    return future.result()
           ^^^^^^^^^^^^^^^
  File "/home/ar1ess/projects/crypto/brain/main.py", line 372, in main
    await analyst.start_update()
  File "/home/ar1ess/projects/crypto/brain/Core/Analyst.py", line 227, in start_update
    await self.scout.start_monitoring()
  File "/home/ar1ess/projects/crypto/brain/Core/scouts/ScoutDad.py", line 27, in start_monitoring
    await asyncio.gather(*tasks, return_exceptions=True)
asyncio.exceptions.CancelledError

During handling of the above exception, another exception occurred:

Traceback (most recent call last):
  File "/usr/lib/python3.12/asyncio/runners.py", line 194, in run
    return runner.run(main)
           ^^^^^^^^^^^^^^^^
  File "/usr/lib/python3.12/asyncio/runners.py", line 123, in run
    raise KeyboardInterrupt()
KeyboardInterrupt

During handling of the above exception, another exception occurred:

Traceback (most recent call last):
  File "/usr/lib/python3.12/asyncio/events.py", line 88, in _run
    self._context.run(self._callback, *self._args)
  File "/home/ar1ess/projects/crypto/.venv/lib/python3.12/site-packages/ccxt/async_support/base/ws/client.py", line 130, in after_interrupt
    exception = resolved.exception()
                ^^^^^^^^^^^^^^^^^^^^
  File "/home/ar1ess/projects/crypto/.venv/lib/python3.12/site-packages/aiohttp/client_ws.py", line 336, in receive
    msg = await self._reader.read()
          ^^^^^^^^^^^^^^^^^^^^^^^^^
  File "aiohttp/_websocket/reader_c.py", line 118, in read
  File "aiohttp/_websocket/reader_c.py", line 115, in aiohttp._websocket.reader_c.WebSocketDataQueue.read
asyncio.exceptions.CancelledError
2025-10-19 17:12:52,551 - asyncio - ERROR - Exception in callback Future.race.<locals>.callback(<Task cancell...tasks.py:435>>) at /home/ar1ess/projects/crypto/.venv/lib/python3.12/site-packages/ccxt/async_support/base/ws/future.py:22
handle: <Handle Future.race.<locals>.callback(<Task cancell...tasks.py:435>>) at /home/ar1ess/projects/crypto/.venv/lib/python3.12/site-packages/ccxt/async_support/base/ws/future.py:22>
Traceback (most recent call last):
  File "/usr/lib/python3.12/asyncio/runners.py", line 118, in run
    return self._loop.run_until_complete(task)
           ^^^^^^^^^^^^^^^^^^^^^^^^^^^^^^^^^^^
  File "/usr/lib/python3.12/asyncio/base_events.py", line 687, in run_until_complete
    return future.result()
           ^^^^^^^^^^^^^^^
  File "/home/ar1ess/projects/crypto/brain/main.py", line 372, in main
    await analyst.start_update()
  File "/home/ar1ess/projects/crypto/brain/Core/Analyst.py", line 227, in start_update
    await self.scout.start_monitoring()
  File "/home/ar1ess/projects/crypto/brain/Core/scouts/ScoutDad.py", line 27, in start_monitoring
    await asyncio.gather(*tasks, return_exceptions=True)
asyncio.exceptions.CancelledError

During handling of the above exception, another exception occurred:

Traceback (most recent call last):
  File "/usr/lib/python3.12/asyncio/runners.py", line 194, in run
    return runner.run(main)
           ^^^^^^^^^^^^^^^^
  File "/usr/lib/python3.12/asyncio/runners.py", line 123, in run
    raise KeyboardInterrupt()
KeyboardInterrupt

During handling of the above exception, another exception occurred:

Traceback (most recent call last):
  File "/usr/lib/python3.12/asyncio/events.py", line 88, in _run
    self._context.run(self._callback, *self._args)
  File "/home/ar1ess/projects/crypto/.venv/lib/python3.12/site-packages/ccxt/async_support/base/ws/future.py", line 23, in callback
    complete, _ = done.result()
                  ^^^^^^^^^^^^^
  File "/usr/lib/python3.12/asyncio/tasks.py", line 464, in wait
    return await _wait(fs, timeout, return_when, loop)
           ^^^^^^^^^^^^^^^^^^^^^^^^^^^^^^^^^^^^^^^^^^^
  File "/usr/lib/python3.12/asyncio/tasks.py", line 550, in _wait
    await waiter
asyncio.exceptions.CancelledError
2025-10-19 17:17:06,825 - asyncio - ERROR - Exception in callback Future.race.<locals>.callback(<Task cancell...tasks.py:435>>) at /home/ar1ess/projects/crypto/.venv/lib/python3.12/site-packages/ccxt/async_support/base/ws/future.py:22
handle: <Handle Future.race.<locals>.callback(<Task cancell...tasks.py:435>>) at /home/ar1ess/projects/crypto/.venv/lib/python3.12/site-packages/ccxt/async_support/base/ws/future.py:22>
Traceback (most recent call last):
  File "/usr/lib/python3.12/asyncio/runners.py", line 118, in run
    return self._loop.run_until_complete(task)
           ^^^^^^^^^^^^^^^^^^^^^^^^^^^^^^^^^^^
  File "/usr/lib/python3.12/asyncio/base_events.py", line 687, in run_until_complete
    return future.result()
           ^^^^^^^^^^^^^^^
  File "/home/ar1ess/projects/crypto/brain/main.py", line 372, in main
    await analyst.start_update()
  File "/home/ar1ess/projects/crypto/brain/Core/Analyst.py", line 227, in start_update
    await self.scout.start_monitoring()
  File "/home/ar1ess/projects/crypto/brain/Core/scouts/ScoutDad.py", line 27, in start_monitoring
    await asyncio.gather(*tasks, return_exceptions=True)
  File "/home/ar1ess/projects/crypto/brain/Core/scouts/ScoutDad.py", line 33, in _monitor_scout
    async for assets in scout.watch_tickers():
  File "/home/ar1ess/projects/crypto/brain/Core/scouts/ScoutOkx.py", line 16, in watch_tickers
    tickers = await self.ccxt_exchange.watch_tickers(symbols, params)
              ^^^^^^^^^^^^^^^^^^^^^^^^^^^^^^^^^^^^^^^^^^^^^^^^^^^^^^^
  File "/home/ar1ess/projects/crypto/.venv/lib/python3.12/site-packages/ccxt/pro/okx.py", line 454, in watch_tickers
    newTickers = await self.subscribe_multiple('public', channel, symbols, params)
                 ^^^^^^^^^^^^^^^^^^^^^^^^^^^^^^^^^^^^^^^^^^^^^^^^^^^^^^^^^^^^^^^^^
  File "/home/ar1ess/projects/crypto/.venv/lib/python3.12/site-packages/ccxt/pro/okx.py", line 153, in subscribe_multiple
    return await self.watch_multiple(url, messageHashes, request, messageHashes)
           ^^^^^^^^^^^^^^^^^^^^^^^^^^^^^^^^^^^^^^^^^^^^^^^^^^^^^^^^^^^^^^^^^^^^^
asyncio.exceptions.CancelledError

During handling of the above exception, another exception occurred:

Traceback (most recent call last):
  File "/usr/lib/python3.12/asyncio/runners.py", line 194, in run
    return runner.run(main)
           ^^^^^^^^^^^^^^^^
  File "/usr/lib/python3.12/asyncio/runners.py", line 123, in run
    raise KeyboardInterrupt()
KeyboardInterrupt

During handling of the above exception, another exception occurred:

Traceback (most recent call last):
  File "/usr/lib/python3.12/asyncio/events.py", line 88, in _run
    self._context.run(self._callback, *self._args)
  File "/home/ar1ess/projects/crypto/.venv/lib/python3.12/site-packages/ccxt/async_support/base/ws/future.py", line 23, in callback
    complete, _ = done.result()
                  ^^^^^^^^^^^^^
  File "/usr/lib/python3.12/asyncio/tasks.py", line 464, in wait
    return await _wait(fs, timeout, return_when, loop)
           ^^^^^^^^^^^^^^^^^^^^^^^^^^^^^^^^^^^^^^^^^^^
  File "/usr/lib/python3.12/asyncio/tasks.py", line 550, in _wait
    await waiter
asyncio.exceptions.CancelledError
2025-10-19 17:17:06,837 - asyncio - ERROR - Exception in callback Future.race.<locals>.callback(<Task cancell...tasks.py:435>>) at /home/ar1ess/projects/crypto/.venv/lib/python3.12/site-packages/ccxt/async_support/base/ws/future.py:22
handle: <Handle Future.race.<locals>.callback(<Task cancell...tasks.py:435>>) at /home/ar1ess/projects/crypto/.venv/lib/python3.12/site-packages/ccxt/async_support/base/ws/future.py:22>
Traceback (most recent call last):
  File "/usr/lib/python3.12/asyncio/runners.py", line 118, in run
    return self._loop.run_until_complete(task)
           ^^^^^^^^^^^^^^^^^^^^^^^^^^^^^^^^^^^
  File "/usr/lib/python3.12/asyncio/base_events.py", line 687, in run_until_complete
    return future.result()
           ^^^^^^^^^^^^^^^
  File "/home/ar1ess/projects/crypto/brain/main.py", line 372, in main
    await analyst.start_update()
  File "/home/ar1ess/projects/crypto/brain/Core/Analyst.py", line 227, in start_update
    await self.scout.start_monitoring()
  File "/home/ar1ess/projects/crypto/brain/Core/scouts/ScoutDad.py", line 27, in start_monitoring
    await asyncio.gather(*tasks, return_exceptions=True)
  File "/home/ar1ess/projects/crypto/brain/Core/scouts/ScoutDad.py", line 33, in _monitor_scout
    async for assets in scout.watch_tickers():
  File "/home/ar1ess/projects/crypto/brain/Core/scouts/ScoutOkx.py", line 16, in watch_tickers
    tickers = await self.ccxt_exchange.watch_tickers(symbols, params)
              ^^^^^^^^^^^^^^^^^^^^^^^^^^^^^^^^^^^^^^^^^^^^^^^^^^^^^^^
  File "/home/ar1ess/projects/crypto/.venv/lib/python3.12/site-packages/ccxt/pro/okx.py", line 454, in watch_tickers
    newTickers = await self.subscribe_multiple('public', channel, symbols, params)
                 ^^^^^^^^^^^^^^^^^^^^^^^^^^^^^^^^^^^^^^^^^^^^^^^^^^^^^^^^^^^^^^^^^
  File "/home/ar1ess/projects/crypto/.venv/lib/python3.12/site-packages/ccxt/pro/okx.py", line 153, in subscribe_multiple
    return await self.watch_multiple(url, messageHashes, request, messageHashes)
           ^^^^^^^^^^^^^^^^^^^^^^^^^^^^^^^^^^^^^^^^^^^^^^^^^^^^^^^^^^^^^^^^^^^^^
asyncio.exceptions.CancelledError

During handling of the above exception, another exception occurred:

Traceback (most recent call last):
  File "/usr/lib/python3.12/asyncio/runners.py", line 194, in run
    return runner.run(main)
           ^^^^^^^^^^^^^^^^
  File "/usr/lib/python3.12/asyncio/runners.py", line 123, in run
    raise KeyboardInterrupt()
KeyboardInterrupt

During handling of the above exception, another exception occurred:

Traceback (most recent call last):
  File "/usr/lib/python3.12/asyncio/events.py", line 88, in _run
    self._context.run(self._callback, *self._args)
  File "/home/ar1ess/projects/crypto/.venv/lib/python3.12/site-packages/ccxt/async_support/base/ws/future.py", line 23, in callback
    complete, _ = done.result()
                  ^^^^^^^^^^^^^
  File "/usr/lib/python3.12/asyncio/tasks.py", line 464, in wait
    return await _wait(fs, timeout, return_when, loop)
           ^^^^^^^^^^^^^^^^^^^^^^^^^^^^^^^^^^^^^^^^^^^
  File "/usr/lib/python3.12/asyncio/tasks.py", line 550, in _wait
    await waiter
asyncio.exceptions.CancelledError
2025-10-19 17:17:06,838 - asyncio - ERROR - Exception in callback Client.receive_loop.<locals>.after_interrupt(<Task cancell...nt_ws.py:312>>) at /home/ar1ess/projects/crypto/.venv/lib/python3.12/site-packages/ccxt/async_support/base/ws/client.py:129
handle: <Handle Client.receive_loop.<locals>.after_interrupt(<Task cancell...nt_ws.py:312>>) at /home/ar1ess/projects/crypto/.venv/lib/python3.12/site-packages/ccxt/async_support/base/ws/client.py:129>
Traceback (most recent call last):
  File "/usr/lib/python3.12/asyncio/runners.py", line 118, in run
    return self._loop.run_until_complete(task)
           ^^^^^^^^^^^^^^^^^^^^^^^^^^^^^^^^^^^
  File "/usr/lib/python3.12/asyncio/base_events.py", line 687, in run_until_complete
    return future.result()
           ^^^^^^^^^^^^^^^
  File "/home/ar1ess/projects/crypto/brain/main.py", line 372, in main
    await analyst.start_update()
  File "/home/ar1ess/projects/crypto/brain/Core/Analyst.py", line 227, in start_update
    await self.scout.start_monitoring()
  File "/home/ar1ess/projects/crypto/brain/Core/scouts/ScoutDad.py", line 27, in start_monitoring
    await asyncio.gather(*tasks, return_exceptions=True)
  File "/home/ar1ess/projects/crypto/brain/Core/scouts/ScoutDad.py", line 33, in _monitor_scout
    async for assets in scout.watch_tickers():
  File "/home/ar1ess/projects/crypto/brain/Core/scouts/ScoutOkx.py", line 16, in watch_tickers
    tickers = await self.ccxt_exchange.watch_tickers(symbols, params)
              ^^^^^^^^^^^^^^^^^^^^^^^^^^^^^^^^^^^^^^^^^^^^^^^^^^^^^^^
  File "/home/ar1ess/projects/crypto/.venv/lib/python3.12/site-packages/ccxt/pro/okx.py", line 454, in watch_tickers
    newTickers = await self.subscribe_multiple('public', channel, symbols, params)
                 ^^^^^^^^^^^^^^^^^^^^^^^^^^^^^^^^^^^^^^^^^^^^^^^^^^^^^^^^^^^^^^^^^
  File "/home/ar1ess/projects/crypto/.venv/lib/python3.12/site-packages/ccxt/pro/okx.py", line 153, in subscribe_multiple
    return await self.watch_multiple(url, messageHashes, request, messageHashes)
           ^^^^^^^^^^^^^^^^^^^^^^^^^^^^^^^^^^^^^^^^^^^^^^^^^^^^^^^^^^^^^^^^^^^^^
asyncio.exceptions.CancelledError

During handling of the above exception, another exception occurred:

Traceback (most recent call last):
  File "/usr/lib/python3.12/asyncio/runners.py", line 194, in run
    return runner.run(main)
           ^^^^^^^^^^^^^^^^
  File "/usr/lib/python3.12/asyncio/runners.py", line 123, in run
    raise KeyboardInterrupt()
KeyboardInterrupt

During handling of the above exception, another exception occurred:

Traceback (most recent call last):
  File "/usr/lib/python3.12/asyncio/events.py", line 88, in _run
    self._context.run(self._callback, *self._args)
  File "/home/ar1ess/projects/crypto/.venv/lib/python3.12/site-packages/ccxt/async_support/base/ws/client.py", line 130, in after_interrupt
    exception = resolved.exception()
                ^^^^^^^^^^^^^^^^^^^^
  File "/home/ar1ess/projects/crypto/.venv/lib/python3.12/site-packages/aiohttp/client_ws.py", line 336, in receive
    msg = await self._reader.read()
          ^^^^^^^^^^^^^^^^^^^^^^^^^
  File "aiohttp/_websocket/reader_c.py", line 118, in read
  File "aiohttp/_websocket/reader_c.py", line 115, in aiohttp._websocket.reader_c.WebSocketDataQueue.read
asyncio.exceptions.CancelledError
2025-10-19 17:17:06,840 - asyncio - ERROR - Exception in callback Client.receive_loop.<locals>.after_interrupt(<Task cancell...nt_ws.py:312>>) at /home/ar1ess/projects/crypto/.venv/lib/python3.12/site-packages/ccxt/async_support/base/ws/client.py:129
handle: <Handle Client.receive_loop.<locals>.after_interrupt(<Task cancell...nt_ws.py:312>>) at /home/ar1ess/projects/crypto/.venv/lib/python3.12/site-packages/ccxt/async_support/base/ws/client.py:129>
Traceback (most recent call last):
  File "/usr/lib/python3.12/asyncio/runners.py", line 118, in run
    return self._loop.run_until_complete(task)
           ^^^^^^^^^^^^^^^^^^^^^^^^^^^^^^^^^^^
  File "/usr/lib/python3.12/asyncio/base_events.py", line 687, in run_until_complete
    return future.result()
           ^^^^^^^^^^^^^^^
  File "/home/ar1ess/projects/crypto/brain/main.py", line 372, in main
    await analyst.start_update()
  File "/home/ar1ess/projects/crypto/brain/Core/Analyst.py", line 227, in start_update
    await self.scout.start_monitoring()
  File "/home/ar1ess/projects/crypto/brain/Core/scouts/ScoutDad.py", line 27, in start_monitoring
    await asyncio.gather(*tasks, return_exceptions=True)
  File "/home/ar1ess/projects/crypto/brain/Core/scouts/ScoutDad.py", line 33, in _monitor_scout
    async for assets in scout.watch_tickers():
  File "/home/ar1ess/projects/crypto/brain/Core/scouts/ScoutOkx.py", line 16, in watch_tickers
    tickers = await self.ccxt_exchange.watch_tickers(symbols, params)
              ^^^^^^^^^^^^^^^^^^^^^^^^^^^^^^^^^^^^^^^^^^^^^^^^^^^^^^^
  File "/home/ar1ess/projects/crypto/.venv/lib/python3.12/site-packages/ccxt/pro/okx.py", line 454, in watch_tickers
    newTickers = await self.subscribe_multiple('public', channel, symbols, params)
                 ^^^^^^^^^^^^^^^^^^^^^^^^^^^^^^^^^^^^^^^^^^^^^^^^^^^^^^^^^^^^^^^^^
  File "/home/ar1ess/projects/crypto/.venv/lib/python3.12/site-packages/ccxt/pro/okx.py", line 153, in subscribe_multiple
    return await self.watch_multiple(url, messageHashes, request, messageHashes)
           ^^^^^^^^^^^^^^^^^^^^^^^^^^^^^^^^^^^^^^^^^^^^^^^^^^^^^^^^^^^^^^^^^^^^^
asyncio.exceptions.CancelledError

During handling of the above exception, another exception occurred:

Traceback (most recent call last):
  File "/usr/lib/python3.12/asyncio/runners.py", line 194, in run
    return runner.run(main)
           ^^^^^^^^^^^^^^^^
  File "/usr/lib/python3.12/asyncio/runners.py", line 123, in run
    raise KeyboardInterrupt()
KeyboardInterrupt

During handling of the above exception, another exception occurred:

Traceback (most recent call last):
  File "/usr/lib/python3.12/asyncio/events.py", line 88, in _run
    self._context.run(self._callback, *self._args)
  File "/home/ar1ess/projects/crypto/.venv/lib/python3.12/site-packages/ccxt/async_support/base/ws/client.py", line 130, in after_interrupt
    exception = resolved.exception()
                ^^^^^^^^^^^^^^^^^^^^
  File "/home/ar1ess/projects/crypto/.venv/lib/python3.12/site-packages/aiohttp/client_ws.py", line 336, in receive
    msg = await self._reader.read()
          ^^^^^^^^^^^^^^^^^^^^^^^^^
  File "aiohttp/_websocket/reader_c.py", line 118, in read
  File "aiohttp/_websocket/reader_c.py", line 115, in aiohttp._websocket.reader_c.WebSocketDataQueue.read
asyncio.exceptions.CancelledError
2025-10-19 17:17:06,840 - asyncio - ERROR - Exception in callback Future.race.<locals>.callback(<Task cancell...tasks.py:435>>) at /home/ar1ess/projects/crypto/.venv/lib/python3.12/site-packages/ccxt/async_support/base/ws/future.py:22
handle: <Handle Future.race.<locals>.callback(<Task cancell...tasks.py:435>>) at /home/ar1ess/projects/crypto/.venv/lib/python3.12/site-packages/ccxt/async_support/base/ws/future.py:22>
Traceback (most recent call last):
  File "/usr/lib/python3.12/asyncio/runners.py", line 118, in run
    return self._loop.run_until_complete(task)
           ^^^^^^^^^^^^^^^^^^^^^^^^^^^^^^^^^^^
  File "/usr/lib/python3.12/asyncio/base_events.py", line 687, in run_until_complete
    return future.result()
           ^^^^^^^^^^^^^^^
  File "/home/ar1ess/projects/crypto/brain/main.py", line 372, in main
    await analyst.start_update()
  File "/home/ar1ess/projects/crypto/brain/Core/Analyst.py", line 227, in start_update
    await self.scout.start_monitoring()
  File "/home/ar1ess/projects/crypto/brain/Core/scouts/ScoutDad.py", line 27, in start_monitoring
    await asyncio.gather(*tasks, return_exceptions=True)
  File "/home/ar1ess/projects/crypto/brain/Core/scouts/ScoutDad.py", line 33, in _monitor_scout
    async for assets in scout.watch_tickers():
  File "/home/ar1ess/projects/crypto/brain/Core/scouts/ScoutOkx.py", line 16, in watch_tickers
    tickers = await self.ccxt_exchange.watch_tickers(symbols, params)
              ^^^^^^^^^^^^^^^^^^^^^^^^^^^^^^^^^^^^^^^^^^^^^^^^^^^^^^^
  File "/home/ar1ess/projects/crypto/.venv/lib/python3.12/site-packages/ccxt/pro/okx.py", line 454, in watch_tickers
    newTickers = await self.subscribe_multiple('public', channel, symbols, params)
                 ^^^^^^^^^^^^^^^^^^^^^^^^^^^^^^^^^^^^^^^^^^^^^^^^^^^^^^^^^^^^^^^^^
  File "/home/ar1ess/projects/crypto/.venv/lib/python3.12/site-packages/ccxt/pro/okx.py", line 153, in subscribe_multiple
    return await self.watch_multiple(url, messageHashes, request, messageHashes)
           ^^^^^^^^^^^^^^^^^^^^^^^^^^^^^^^^^^^^^^^^^^^^^^^^^^^^^^^^^^^^^^^^^^^^^
asyncio.exceptions.CancelledError

During handling of the above exception, another exception occurred:

Traceback (most recent call last):
  File "/usr/lib/python3.12/asyncio/runners.py", line 194, in run
    return runner.run(main)
           ^^^^^^^^^^^^^^^^
  File "/usr/lib/python3.12/asyncio/runners.py", line 123, in run
    raise KeyboardInterrupt()
KeyboardInterrupt

During handling of the above exception, another exception occurred:

Traceback (most recent call last):
  File "/usr/lib/python3.12/asyncio/events.py", line 88, in _run
    self._context.run(self._callback, *self._args)
  File "/home/ar1ess/projects/crypto/.venv/lib/python3.12/site-packages/ccxt/async_support/base/ws/future.py", line 23, in callback
    complete, _ = done.result()
                  ^^^^^^^^^^^^^
  File "/usr/lib/python3.12/asyncio/tasks.py", line 464, in wait
    return await _wait(fs, timeout, return_when, loop)
           ^^^^^^^^^^^^^^^^^^^^^^^^^^^^^^^^^^^^^^^^^^^
  File "/usr/lib/python3.12/asyncio/tasks.py", line 550, in _wait
    await waiter
asyncio.exceptions.CancelledError
2025-10-19 17:17:06,841 - asyncio - ERROR - Exception in callback Future.race.<locals>.callback(<Task cancell...tasks.py:435>>) at /home/ar1ess/projects/crypto/.venv/lib/python3.12/site-packages/ccxt/async_support/base/ws/future.py:22
handle: <Handle Future.race.<locals>.callback(<Task cancell...tasks.py:435>>) at /home/ar1ess/projects/crypto/.venv/lib/python3.12/site-packages/ccxt/async_support/base/ws/future.py:22>
Traceback (most recent call last):
  File "/usr/lib/python3.12/asyncio/runners.py", line 118, in run
    return self._loop.run_until_complete(task)
           ^^^^^^^^^^^^^^^^^^^^^^^^^^^^^^^^^^^
  File "/usr/lib/python3.12/asyncio/base_events.py", line 687, in run_until_complete
    return future.result()
           ^^^^^^^^^^^^^^^
  File "/home/ar1ess/projects/crypto/brain/main.py", line 372, in main
    await analyst.start_update()
  File "/home/ar1ess/projects/crypto/brain/Core/Analyst.py", line 227, in start_update
    await self.scout.start_monitoring()
  File "/home/ar1ess/projects/crypto/brain/Core/scouts/ScoutDad.py", line 27, in start_monitoring
    await asyncio.gather(*tasks, return_exceptions=True)
  File "/home/ar1ess/projects/crypto/brain/Core/scouts/ScoutDad.py", line 33, in _monitor_scout
    async for assets in scout.watch_tickers():
  File "/home/ar1ess/projects/crypto/brain/Core/scouts/ScoutOkx.py", line 16, in watch_tickers
    tickers = await self.ccxt_exchange.watch_tickers(symbols, params)
              ^^^^^^^^^^^^^^^^^^^^^^^^^^^^^^^^^^^^^^^^^^^^^^^^^^^^^^^
  File "/home/ar1ess/projects/crypto/.venv/lib/python3.12/site-packages/ccxt/pro/okx.py", line 454, in watch_tickers
    newTickers = await self.subscribe_multiple('public', channel, symbols, params)
                 ^^^^^^^^^^^^^^^^^^^^^^^^^^^^^^^^^^^^^^^^^^^^^^^^^^^^^^^^^^^^^^^^^
  File "/home/ar1ess/projects/crypto/.venv/lib/python3.12/site-packages/ccxt/pro/okx.py", line 153, in subscribe_multiple
    return await self.watch_multiple(url, messageHashes, request, messageHashes)
           ^^^^^^^^^^^^^^^^^^^^^^^^^^^^^^^^^^^^^^^^^^^^^^^^^^^^^^^^^^^^^^^^^^^^^
asyncio.exceptions.CancelledError

During handling of the above exception, another exception occurred:

Traceback (most recent call last):
  File "/usr/lib/python3.12/asyncio/runners.py", line 194, in run
    return runner.run(main)
           ^^^^^^^^^^^^^^^^
  File "/usr/lib/python3.12/asyncio/runners.py", line 123, in run
    raise KeyboardInterrupt()
KeyboardInterrupt

During handling of the above exception, another exception occurred:

Traceback (most recent call last):
  File "/usr/lib/python3.12/asyncio/events.py", line 88, in _run
    self._context.run(self._callback, *self._args)
  File "/home/ar1ess/projects/crypto/.venv/lib/python3.12/site-packages/ccxt/async_support/base/ws/future.py", line 23, in callback
    complete, _ = done.result()
                  ^^^^^^^^^^^^^
  File "/usr/lib/python3.12/asyncio/tasks.py", line 464, in wait
    return await _wait(fs, timeout, return_when, loop)
           ^^^^^^^^^^^^^^^^^^^^^^^^^^^^^^^^^^^^^^^^^^^
  File "/usr/lib/python3.12/asyncio/tasks.py", line 550, in _wait
    await waiter
asyncio.exceptions.CancelledError
2025-10-19 17:17:06,842 - asyncio - ERROR - Exception in callback Client.receive_loop.<locals>.after_interrupt(<Task cancell...nt_ws.py:312>>) at /home/ar1ess/projects/crypto/.venv/lib/python3.12/site-packages/ccxt/async_support/base/ws/client.py:129
handle: <Handle Client.receive_loop.<locals>.after_interrupt(<Task cancell...nt_ws.py:312>>) at /home/ar1ess/projects/crypto/.venv/lib/python3.12/site-packages/ccxt/async_support/base/ws/client.py:129>
Traceback (most recent call last):
  File "/usr/lib/python3.12/asyncio/runners.py", line 118, in run
    return self._loop.run_until_complete(task)
           ^^^^^^^^^^^^^^^^^^^^^^^^^^^^^^^^^^^
  File "/usr/lib/python3.12/asyncio/base_events.py", line 687, in run_until_complete
    return future.result()
           ^^^^^^^^^^^^^^^
  File "/home/ar1ess/projects/crypto/brain/main.py", line 372, in main
    await analyst.start_update()
  File "/home/ar1ess/projects/crypto/brain/Core/Analyst.py", line 227, in start_update
    await self.scout.start_monitoring()
  File "/home/ar1ess/projects/crypto/brain/Core/scouts/ScoutDad.py", line 27, in start_monitoring
    await asyncio.gather(*tasks, return_exceptions=True)
  File "/home/ar1ess/projects/crypto/brain/Core/scouts/ScoutDad.py", line 33, in _monitor_scout
    async for assets in scout.watch_tickers():
  File "/home/ar1ess/projects/crypto/brain/Core/scouts/ScoutOkx.py", line 16, in watch_tickers
    tickers = await self.ccxt_exchange.watch_tickers(symbols, params)
              ^^^^^^^^^^^^^^^^^^^^^^^^^^^^^^^^^^^^^^^^^^^^^^^^^^^^^^^
  File "/home/ar1ess/projects/crypto/.venv/lib/python3.12/site-packages/ccxt/pro/okx.py", line 454, in watch_tickers
    newTickers = await self.subscribe_multiple('public', channel, symbols, params)
                 ^^^^^^^^^^^^^^^^^^^^^^^^^^^^^^^^^^^^^^^^^^^^^^^^^^^^^^^^^^^^^^^^^
  File "/home/ar1ess/projects/crypto/.venv/lib/python3.12/site-packages/ccxt/pro/okx.py", line 153, in subscribe_multiple
    return await self.watch_multiple(url, messageHashes, request, messageHashes)
           ^^^^^^^^^^^^^^^^^^^^^^^^^^^^^^^^^^^^^^^^^^^^^^^^^^^^^^^^^^^^^^^^^^^^^
asyncio.exceptions.CancelledError

During handling of the above exception, another exception occurred:

Traceback (most recent call last):
  File "/usr/lib/python3.12/asyncio/runners.py", line 194, in run
    return runner.run(main)
           ^^^^^^^^^^^^^^^^
  File "/usr/lib/python3.12/asyncio/runners.py", line 123, in run
    raise KeyboardInterrupt()
KeyboardInterrupt

During handling of the above exception, another exception occurred:

Traceback (most recent call last):
  File "/usr/lib/python3.12/asyncio/events.py", line 88, in _run
    self._context.run(self._callback, *self._args)
  File "/home/ar1ess/projects/crypto/.venv/lib/python3.12/site-packages/ccxt/async_support/base/ws/client.py", line 130, in after_interrupt
    exception = resolved.exception()
                ^^^^^^^^^^^^^^^^^^^^
  File "/home/ar1ess/projects/crypto/.venv/lib/python3.12/site-packages/aiohttp/client_ws.py", line 336, in receive
    msg = await self._reader.read()
          ^^^^^^^^^^^^^^^^^^^^^^^^^
  File "aiohttp/_websocket/reader_c.py", line 118, in read
  File "aiohttp/_websocket/reader_c.py", line 115, in aiohttp._websocket.reader_c.WebSocketDataQueue.read
asyncio.exceptions.CancelledError
2025-10-19 17:17:06,843 - asyncio - ERROR - Exception in callback Client.receive_loop.<locals>.after_interrupt(<Task cancell...nt_ws.py:312>>) at /home/ar1ess/projects/crypto/.venv/lib/python3.12/site-packages/ccxt/async_support/base/ws/client.py:129
handle: <Handle Client.receive_loop.<locals>.after_interrupt(<Task cancell...nt_ws.py:312>>) at /home/ar1ess/projects/crypto/.venv/lib/python3.12/site-packages/ccxt/async_support/base/ws/client.py:129>
Traceback (most recent call last):
  File "/usr/lib/python3.12/asyncio/runners.py", line 118, in run
    return self._loop.run_until_complete(task)
           ^^^^^^^^^^^^^^^^^^^^^^^^^^^^^^^^^^^
  File "/usr/lib/python3.12/asyncio/base_events.py", line 687, in run_until_complete
    return future.result()
           ^^^^^^^^^^^^^^^
  File "/home/ar1ess/projects/crypto/brain/main.py", line 372, in main
    await analyst.start_update()
  File "/home/ar1ess/projects/crypto/brain/Core/Analyst.py", line 227, in start_update
    await self.scout.start_monitoring()
  File "/home/ar1ess/projects/crypto/brain/Core/scouts/ScoutDad.py", line 27, in start_monitoring
    await asyncio.gather(*tasks, return_exceptions=True)
  File "/home/ar1ess/projects/crypto/brain/Core/scouts/ScoutDad.py", line 33, in _monitor_scout
    async for assets in scout.watch_tickers():
  File "/home/ar1ess/projects/crypto/brain/Core/scouts/ScoutOkx.py", line 16, in watch_tickers
    tickers = await self.ccxt_exchange.watch_tickers(symbols, params)
              ^^^^^^^^^^^^^^^^^^^^^^^^^^^^^^^^^^^^^^^^^^^^^^^^^^^^^^^
  File "/home/ar1ess/projects/crypto/.venv/lib/python3.12/site-packages/ccxt/pro/okx.py", line 454, in watch_tickers
    newTickers = await self.subscribe_multiple('public', channel, symbols, params)
                 ^^^^^^^^^^^^^^^^^^^^^^^^^^^^^^^^^^^^^^^^^^^^^^^^^^^^^^^^^^^^^^^^^
  File "/home/ar1ess/projects/crypto/.venv/lib/python3.12/site-packages/ccxt/pro/okx.py", line 153, in subscribe_multiple
    return await self.watch_multiple(url, messageHashes, request, messageHashes)
           ^^^^^^^^^^^^^^^^^^^^^^^^^^^^^^^^^^^^^^^^^^^^^^^^^^^^^^^^^^^^^^^^^^^^^
asyncio.exceptions.CancelledError

During handling of the above exception, another exception occurred:

Traceback (most recent call last):
  File "/usr/lib/python3.12/asyncio/runners.py", line 194, in run
    return runner.run(main)
           ^^^^^^^^^^^^^^^^
  File "/usr/lib/python3.12/asyncio/runners.py", line 123, in run
    raise KeyboardInterrupt()
KeyboardInterrupt

During handling of the above exception, another exception occurred:

Traceback (most recent call last):
  File "/usr/lib/python3.12/asyncio/events.py", line 88, in _run
    self._context.run(self._callback, *self._args)
  File "/home/ar1ess/projects/crypto/.venv/lib/python3.12/site-packages/ccxt/async_support/base/ws/client.py", line 130, in after_interrupt
    exception = resolved.exception()
                ^^^^^^^^^^^^^^^^^^^^
  File "/home/ar1ess/projects/crypto/.venv/lib/python3.12/site-packages/aiohttp/client_ws.py", line 336, in receive
    msg = await self._reader.read()
          ^^^^^^^^^^^^^^^^^^^^^^^^^
  File "aiohttp/_websocket/reader_c.py", line 118, in read
  File "aiohttp/_websocket/reader_c.py", line 115, in aiohttp._websocket.reader_c.WebSocketDataQueue.read
asyncio.exceptions.CancelledError
2025-10-19 17:17:06,843 - asyncio - ERROR - Exception in callback Future.race.<locals>.callback(<Task cancell...tasks.py:435>>) at /home/ar1ess/projects/crypto/.venv/lib/python3.12/site-packages/ccxt/async_support/base/ws/future.py:22
handle: <Handle Future.race.<locals>.callback(<Task cancell...tasks.py:435>>) at /home/ar1ess/projects/crypto/.venv/lib/python3.12/site-packages/ccxt/async_support/base/ws/future.py:22>
Traceback (most recent call last):
  File "/usr/lib/python3.12/asyncio/runners.py", line 118, in run
    return self._loop.run_until_complete(task)
           ^^^^^^^^^^^^^^^^^^^^^^^^^^^^^^^^^^^
  File "/usr/lib/python3.12/asyncio/base_events.py", line 687, in run_until_complete
    return future.result()
           ^^^^^^^^^^^^^^^
  File "/home/ar1ess/projects/crypto/brain/main.py", line 372, in main
    await analyst.start_update()
  File "/home/ar1ess/projects/crypto/brain/Core/Analyst.py", line 227, in start_update
    await self.scout.start_monitoring()
  File "/home/ar1ess/projects/crypto/brain/Core/scouts/ScoutDad.py", line 27, in start_monitoring
    await asyncio.gather(*tasks, return_exceptions=True)
  File "/home/ar1ess/projects/crypto/brain/Core/scouts/ScoutDad.py", line 33, in _monitor_scout
    async for assets in scout.watch_tickers():
  File "/home/ar1ess/projects/crypto/brain/Core/scouts/ScoutOkx.py", line 16, in watch_tickers
    tickers = await self.ccxt_exchange.watch_tickers(symbols, params)
              ^^^^^^^^^^^^^^^^^^^^^^^^^^^^^^^^^^^^^^^^^^^^^^^^^^^^^^^
  File "/home/ar1ess/projects/crypto/.venv/lib/python3.12/site-packages/ccxt/pro/okx.py", line 454, in watch_tickers
    newTickers = await self.subscribe_multiple('public', channel, symbols, params)
                 ^^^^^^^^^^^^^^^^^^^^^^^^^^^^^^^^^^^^^^^^^^^^^^^^^^^^^^^^^^^^^^^^^
  File "/home/ar1ess/projects/crypto/.venv/lib/python3.12/site-packages/ccxt/pro/okx.py", line 153, in subscribe_multiple
    return await self.watch_multiple(url, messageHashes, request, messageHashes)
           ^^^^^^^^^^^^^^^^^^^^^^^^^^^^^^^^^^^^^^^^^^^^^^^^^^^^^^^^^^^^^^^^^^^^^
asyncio.exceptions.CancelledError

During handling of the above exception, another exception occurred:

Traceback (most recent call last):
  File "/usr/lib/python3.12/asyncio/runners.py", line 194, in run
    return runner.run(main)
           ^^^^^^^^^^^^^^^^
  File "/usr/lib/python3.12/asyncio/runners.py", line 123, in run
    raise KeyboardInterrupt()
KeyboardInterrupt

During handling of the above exception, another exception occurred:

Traceback (most recent call last):
  File "/usr/lib/python3.12/asyncio/events.py", line 88, in _run
    self._context.run(self._callback, *self._args)
  File "/home/ar1ess/projects/crypto/.venv/lib/python3.12/site-packages/ccxt/async_support/base/ws/future.py", line 23, in callback
    complete, _ = done.result()
                  ^^^^^^^^^^^^^
  File "/usr/lib/python3.12/asyncio/tasks.py", line 464, in wait
    return await _wait(fs, timeout, return_when, loop)
           ^^^^^^^^^^^^^^^^^^^^^^^^^^^^^^^^^^^^^^^^^^^
  File "/usr/lib/python3.12/asyncio/tasks.py", line 550, in _wait
    await waiter
asyncio.exceptions.CancelledError
2025-10-19 17:17:06,844 - asyncio - ERROR - Exception in callback Client.receive_loop.<locals>.after_interrupt(<Task cancell...nt_ws.py:312>>) at /home/ar1ess/projects/crypto/.venv/lib/python3.12/site-packages/ccxt/async_support/base/ws/client.py:129
handle: <Handle Client.receive_loop.<locals>.after_interrupt(<Task cancell...nt_ws.py:312>>) at /home/ar1ess/projects/crypto/.venv/lib/python3.12/site-packages/ccxt/async_support/base/ws/client.py:129>
Traceback (most recent call last):
  File "/usr/lib/python3.12/asyncio/runners.py", line 118, in run
    return self._loop.run_until_complete(task)
           ^^^^^^^^^^^^^^^^^^^^^^^^^^^^^^^^^^^
  File "/usr/lib/python3.12/asyncio/base_events.py", line 687, in run_until_complete
    return future.result()
           ^^^^^^^^^^^^^^^
  File "/home/ar1ess/projects/crypto/brain/main.py", line 372, in main
    await analyst.start_update()
  File "/home/ar1ess/projects/crypto/brain/Core/Analyst.py", line 227, in start_update
    await self.scout.start_monitoring()
  File "/home/ar1ess/projects/crypto/brain/Core/scouts/ScoutDad.py", line 27, in start_monitoring
    await asyncio.gather(*tasks, return_exceptions=True)
  File "/home/ar1ess/projects/crypto/brain/Core/scouts/ScoutDad.py", line 33, in _monitor_scout
    async for assets in scout.watch_tickers():
  File "/home/ar1ess/projects/crypto/brain/Core/scouts/ScoutOkx.py", line 16, in watch_tickers
    tickers = await self.ccxt_exchange.watch_tickers(symbols, params)
              ^^^^^^^^^^^^^^^^^^^^^^^^^^^^^^^^^^^^^^^^^^^^^^^^^^^^^^^
  File "/home/ar1ess/projects/crypto/.venv/lib/python3.12/site-packages/ccxt/pro/okx.py", line 454, in watch_tickers
    newTickers = await self.subscribe_multiple('public', channel, symbols, params)
                 ^^^^^^^^^^^^^^^^^^^^^^^^^^^^^^^^^^^^^^^^^^^^^^^^^^^^^^^^^^^^^^^^^
  File "/home/ar1ess/projects/crypto/.venv/lib/python3.12/site-packages/ccxt/pro/okx.py", line 153, in subscribe_multiple
    return await self.watch_multiple(url, messageHashes, request, messageHashes)
           ^^^^^^^^^^^^^^^^^^^^^^^^^^^^^^^^^^^^^^^^^^^^^^^^^^^^^^^^^^^^^^^^^^^^^
asyncio.exceptions.CancelledError

During handling of the above exception, another exception occurred:

Traceback (most recent call last):
  File "/usr/lib/python3.12/asyncio/runners.py", line 194, in run
    return runner.run(main)
           ^^^^^^^^^^^^^^^^
  File "/usr/lib/python3.12/asyncio/runners.py", line 123, in run
    raise KeyboardInterrupt()
KeyboardInterrupt

During handling of the above exception, another exception occurred:

Traceback (most recent call last):
  File "/usr/lib/python3.12/asyncio/events.py", line 88, in _run
    self._context.run(self._callback, *self._args)
  File "/home/ar1ess/projects/crypto/.venv/lib/python3.12/site-packages/ccxt/async_support/base/ws/client.py", line 130, in after_interrupt
    exception = resolved.exception()
                ^^^^^^^^^^^^^^^^^^^^
  File "/home/ar1ess/projects/crypto/.venv/lib/python3.12/site-packages/aiohttp/client_ws.py", line 336, in receive
    msg = await self._reader.read()
          ^^^^^^^^^^^^^^^^^^^^^^^^^
  File "aiohttp/_websocket/reader_c.py", line 118, in read
  File "aiohttp/_websocket/reader_c.py", line 115, in aiohttp._websocket.reader_c.WebSocketDataQueue.read
asyncio.exceptions.CancelledError
2025-10-19 17:22:56,589 - asyncio - ERROR - Exception in callback Future.race.<locals>.callback(<Task cancell...tasks.py:435>>) at /home/ar1ess/projects/crypto/.venv/lib/python3.12/site-packages/ccxt/async_support/base/ws/future.py:22
handle: <Handle Future.race.<locals>.callback(<Task cancell...tasks.py:435>>) at /home/ar1ess/projects/crypto/.venv/lib/python3.12/site-packages/ccxt/async_support/base/ws/future.py:22>
Traceback (most recent call last):
  File "/usr/lib/python3.12/asyncio/runners.py", line 194, in run
    return runner.run(main)
           ^^^^^^^^^^^^^^^^
  File "/usr/lib/python3.12/asyncio/runners.py", line 118, in run
    return self._loop.run_until_complete(task)
           ^^^^^^^^^^^^^^^^^^^^^^^^^^^^^^^^^^^
  File "/usr/lib/python3.12/asyncio/base_events.py", line 687, in run_until_complete
    return future.result()
           ^^^^^^^^^^^^^^^
  File "/home/ar1ess/projects/crypto/brain/main.py", line 372, in main
    await analyst.start_update()
  File "/home/ar1ess/projects/crypto/brain/Core/Analyst.py", line 231, in start_update
    async for update_coin in self.scout.coin_update():
  File "/home/ar1ess/projects/crypto/brain/Core/scouts/ScoutDad.py", line 19, in coin_update
    print(f"📥 ScoutDad: received from queue - {answer[0].name}: {answer[1].coin.name} = {answer[1].price:.6f}")
                                                                  ^^^^^^^^^^^^^^
AttributeError: 'Assets' object has no attribute 'coin'

During handling of the above exception, another exception occurred:

Traceback (most recent call last):
  File "/usr/lib/python3.12/asyncio/events.py", line 88, in _run
    self._context.run(self._callback, *self._args)
  File "/home/ar1ess/projects/crypto/.venv/lib/python3.12/site-packages/ccxt/async_support/base/ws/future.py", line 23, in callback
    complete, _ = done.result()
                  ^^^^^^^^^^^^^
  File "/usr/lib/python3.12/asyncio/tasks.py", line 464, in wait
    return await _wait(fs, timeout, return_when, loop)
           ^^^^^^^^^^^^^^^^^^^^^^^^^^^^^^^^^^^^^^^^^^^
  File "/usr/lib/python3.12/asyncio/tasks.py", line 550, in _wait
    await waiter
asyncio.exceptions.CancelledError
2025-10-19 17:22:56,595 - asyncio - ERROR - Exception in callback Future.race.<locals>.callback(<Task cancell...tasks.py:435>>) at /home/ar1ess/projects/crypto/.venv/lib/python3.12/site-packages/ccxt/async_support/base/ws/future.py:22
handle: <Handle Future.race.<locals>.callback(<Task cancell...tasks.py:435>>) at /home/ar1ess/projects/crypto/.venv/lib/python3.12/site-packages/ccxt/async_support/base/ws/future.py:22>
Traceback (most recent call last):
  File "/usr/lib/python3.12/asyncio/runners.py", line 194, in run
    return runner.run(main)
           ^^^^^^^^^^^^^^^^
  File "/usr/lib/python3.12/asyncio/runners.py", line 118, in run
    return self._loop.run_until_complete(task)
           ^^^^^^^^^^^^^^^^^^^^^^^^^^^^^^^^^^^
  File "/usr/lib/python3.12/asyncio/base_events.py", line 687, in run_until_complete
    return future.result()
           ^^^^^^^^^^^^^^^
  File "/home/ar1ess/projects/crypto/brain/main.py", line 372, in main
    await analyst.start_update()
  File "/home/ar1ess/projects/crypto/brain/Core/Analyst.py", line 231, in start_update
    async for update_coin in self.scout.coin_update():
  File "/home/ar1ess/projects/crypto/brain/Core/scouts/ScoutDad.py", line 19, in coin_update
    print(f"📥 ScoutDad: received from queue - {answer[0].name}: {answer[1].coin.name} = {answer[1].price:.6f}")
                                                                  ^^^^^^^^^^^^^^
AttributeError: 'Assets' object has no attribute 'coin'

During handling of the above exception, another exception occurred:

Traceback (most recent call last):
  File "/usr/lib/python3.12/asyncio/events.py", line 88, in _run
    self._context.run(self._callback, *self._args)
  File "/home/ar1ess/projects/crypto/.venv/lib/python3.12/site-packages/ccxt/async_support/base/ws/future.py", line 23, in callback
    complete, _ = done.result()
                  ^^^^^^^^^^^^^
  File "/usr/lib/python3.12/asyncio/tasks.py", line 464, in wait
    return await _wait(fs, timeout, return_when, loop)
           ^^^^^^^^^^^^^^^^^^^^^^^^^^^^^^^^^^^^^^^^^^^
  File "/usr/lib/python3.12/asyncio/tasks.py", line 550, in _wait
    await waiter
asyncio.exceptions.CancelledError
2025-10-19 17:22:56,595 - asyncio - ERROR - Exception in callback Future.race.<locals>.callback(<Task cancell...tasks.py:435>>) at /home/ar1ess/projects/crypto/.venv/lib/python3.12/site-packages/ccxt/async_support/base/ws/future.py:22
handle: <Handle Future.race.<locals>.callback(<Task cancell...tasks.py:435>>) at /home/ar1ess/projects/crypto/.venv/lib/python3.12/site-packages/ccxt/async_support/base/ws/future.py:22>
Traceback (most recent call last):
  File "/usr/lib/python3.12/asyncio/runners.py", line 194, in run
    return runner.run(main)
           ^^^^^^^^^^^^^^^^
  File "/usr/lib/python3.12/asyncio/runners.py", line 118, in run
    return self._loop.run_until_complete(task)
           ^^^^^^^^^^^^^^^^^^^^^^^^^^^^^^^^^^^
  File "/usr/lib/python3.12/asyncio/base_events.py", line 687, in run_until_complete
    return future.result()
           ^^^^^^^^^^^^^^^
  File "/home/ar1ess/projects/crypto/brain/main.py", line 372, in main
    await analyst.start_update()
  File "/home/ar1ess/projects/crypto/brain/Core/Analyst.py", line 231, in start_update
    async for update_coin in self.scout.coin_update():
  File "/home/ar1ess/projects/crypto/brain/Core/scouts/ScoutDad.py", line 19, in coin_update
    print(f"📥 ScoutDad: received from queue - {answer[0].name}: {answer[1].coin.name} = {answer[1].price:.6f}")
                                                                  ^^^^^^^^^^^^^^
AttributeError: 'Assets' object has no attribute 'coin'

During handling of the above exception, another exception occurred:

Traceback (most recent call last):
  File "/usr/lib/python3.12/asyncio/events.py", line 88, in _run
    self._context.run(self._callback, *self._args)
  File "/home/ar1ess/projects/crypto/.venv/lib/python3.12/site-packages/ccxt/async_support/base/ws/future.py", line 23, in callback
    complete, _ = done.result()
                  ^^^^^^^^^^^^^
  File "/usr/lib/python3.12/asyncio/tasks.py", line 464, in wait
    return await _wait(fs, timeout, return_when, loop)
           ^^^^^^^^^^^^^^^^^^^^^^^^^^^^^^^^^^^^^^^^^^^
  File "/usr/lib/python3.12/asyncio/tasks.py", line 550, in _wait
    await waiter
asyncio.exceptions.CancelledError
2025-10-19 17:22:56,596 - asyncio - ERROR - Exception in callback Client.receive_loop.<locals>.after_interrupt(<Task cancell...nt_ws.py:312>>) at /home/ar1ess/projects/crypto/.venv/lib/python3.12/site-packages/ccxt/async_support/base/ws/client.py:129
handle: <Handle Client.receive_loop.<locals>.after_interrupt(<Task cancell...nt_ws.py:312>>) at /home/ar1ess/projects/crypto/.venv/lib/python3.12/site-packages/ccxt/async_support/base/ws/client.py:129>
Traceback (most recent call last):
  File "/usr/lib/python3.12/asyncio/runners.py", line 194, in run
    return runner.run(main)
           ^^^^^^^^^^^^^^^^
  File "/usr/lib/python3.12/asyncio/runners.py", line 118, in run
    return self._loop.run_until_complete(task)
           ^^^^^^^^^^^^^^^^^^^^^^^^^^^^^^^^^^^
  File "/usr/lib/python3.12/asyncio/base_events.py", line 687, in run_until_complete
    return future.result()
           ^^^^^^^^^^^^^^^
  File "/home/ar1ess/projects/crypto/brain/main.py", line 372, in main
    await analyst.start_update()
  File "/home/ar1ess/projects/crypto/brain/Core/Analyst.py", line 231, in start_update
    async for update_coin in self.scout.coin_update():
  File "/home/ar1ess/projects/crypto/brain/Core/scouts/ScoutDad.py", line 19, in coin_update
    print(f"📥 ScoutDad: received from queue - {answer[0].name}: {answer[1].coin.name} = {answer[1].price:.6f}")
                                                                  ^^^^^^^^^^^^^^
AttributeError: 'Assets' object has no attribute 'coin'

During handling of the above exception, another exception occurred:

Traceback (most recent call last):
  File "/usr/lib/python3.12/asyncio/events.py", line 88, in _run
    self._context.run(self._callback, *self._args)
  File "/home/ar1ess/projects/crypto/.venv/lib/python3.12/site-packages/ccxt/async_support/base/ws/client.py", line 130, in after_interrupt
    exception = resolved.exception()
                ^^^^^^^^^^^^^^^^^^^^
  File "/home/ar1ess/projects/crypto/.venv/lib/python3.12/site-packages/aiohttp/client_ws.py", line 336, in receive
    msg = await self._reader.read()
          ^^^^^^^^^^^^^^^^^^^^^^^^^
  File "aiohttp/_websocket/reader_c.py", line 118, in read
  File "aiohttp/_websocket/reader_c.py", line 115, in aiohttp._websocket.reader_c.WebSocketDataQueue.read
asyncio.exceptions.CancelledError
2025-10-19 17:22:56,597 - asyncio - ERROR - Exception in callback Future.race.<locals>.callback(<Task cancell...tasks.py:435>>) at /home/ar1ess/projects/crypto/.venv/lib/python3.12/site-packages/ccxt/async_support/base/ws/future.py:22
handle: <Handle Future.race.<locals>.callback(<Task cancell...tasks.py:435>>) at /home/ar1ess/projects/crypto/.venv/lib/python3.12/site-packages/ccxt/async_support/base/ws/future.py:22>
Traceback (most recent call last):
  File "/usr/lib/python3.12/asyncio/runners.py", line 194, in run
    return runner.run(main)
           ^^^^^^^^^^^^^^^^
  File "/usr/lib/python3.12/asyncio/runners.py", line 118, in run
    return self._loop.run_until_complete(task)
           ^^^^^^^^^^^^^^^^^^^^^^^^^^^^^^^^^^^
  File "/usr/lib/python3.12/asyncio/base_events.py", line 687, in run_until_complete
    return future.result()
           ^^^^^^^^^^^^^^^
  File "/home/ar1ess/projects/crypto/brain/main.py", line 372, in main
    await analyst.start_update()
  File "/home/ar1ess/projects/crypto/brain/Core/Analyst.py", line 231, in start_update
    async for update_coin in self.scout.coin_update():
  File "/home/ar1ess/projects/crypto/brain/Core/scouts/ScoutDad.py", line 19, in coin_update
    print(f"📥 ScoutDad: received from queue - {answer[0].name}: {answer[1].coin.name} = {answer[1].price:.6f}")
                                                                  ^^^^^^^^^^^^^^
AttributeError: 'Assets' object has no attribute 'coin'

During handling of the above exception, another exception occurred:

Traceback (most recent call last):
  File "/usr/lib/python3.12/asyncio/events.py", line 88, in _run
    self._context.run(self._callback, *self._args)
  File "/home/ar1ess/projects/crypto/.venv/lib/python3.12/site-packages/ccxt/async_support/base/ws/future.py", line 23, in callback
    complete, _ = done.result()
                  ^^^^^^^^^^^^^
  File "/usr/lib/python3.12/asyncio/tasks.py", line 464, in wait
    return await _wait(fs, timeout, return_when, loop)
           ^^^^^^^^^^^^^^^^^^^^^^^^^^^^^^^^^^^^^^^^^^^
  File "/usr/lib/python3.12/asyncio/tasks.py", line 550, in _wait
    await waiter
asyncio.exceptions.CancelledError
2025-10-19 17:22:56,598 - asyncio - ERROR - Exception in callback Future.race.<locals>.callback(<Task cancell...tasks.py:435>>) at /home/ar1ess/projects/crypto/.venv/lib/python3.12/site-packages/ccxt/async_support/base/ws/future.py:22
handle: <Handle Future.race.<locals>.callback(<Task cancell...tasks.py:435>>) at /home/ar1ess/projects/crypto/.venv/lib/python3.12/site-packages/ccxt/async_support/base/ws/future.py:22>
Traceback (most recent call last):
  File "/usr/lib/python3.12/asyncio/runners.py", line 194, in run
    return runner.run(main)
           ^^^^^^^^^^^^^^^^
  File "/usr/lib/python3.12/asyncio/runners.py", line 118, in run
    return self._loop.run_until_complete(task)
           ^^^^^^^^^^^^^^^^^^^^^^^^^^^^^^^^^^^
  File "/usr/lib/python3.12/asyncio/base_events.py", line 687, in run_until_complete
    return future.result()
           ^^^^^^^^^^^^^^^
  File "/home/ar1ess/projects/crypto/brain/main.py", line 372, in main
    await analyst.start_update()
  File "/home/ar1ess/projects/crypto/brain/Core/Analyst.py", line 231, in start_update
    async for update_coin in self.scout.coin_update():
  File "/home/ar1ess/projects/crypto/brain/Core/scouts/ScoutDad.py", line 19, in coin_update
    print(f"📥 ScoutDad: received from queue - {answer[0].name}: {answer[1].coin.name} = {answer[1].price:.6f}")
                                                                  ^^^^^^^^^^^^^^
AttributeError: 'Assets' object has no attribute 'coin'

During handling of the above exception, another exception occurred:

Traceback (most recent call last):
  File "/usr/lib/python3.12/asyncio/events.py", line 88, in _run
    self._context.run(self._callback, *self._args)
  File "/home/ar1ess/projects/crypto/.venv/lib/python3.12/site-packages/ccxt/async_support/base/ws/future.py", line 23, in callback
    complete, _ = done.result()
                  ^^^^^^^^^^^^^
  File "/usr/lib/python3.12/asyncio/tasks.py", line 464, in wait
    return await _wait(fs, timeout, return_when, loop)
           ^^^^^^^^^^^^^^^^^^^^^^^^^^^^^^^^^^^^^^^^^^^
  File "/usr/lib/python3.12/asyncio/tasks.py", line 550, in _wait
    await waiter
asyncio.exceptions.CancelledError
2025-10-19 17:22:56,598 - asyncio - ERROR - Exception in callback Client.receive_loop.<locals>.after_interrupt(<Task cancell...nt_ws.py:312>>) at /home/ar1ess/projects/crypto/.venv/lib/python3.12/site-packages/ccxt/async_support/base/ws/client.py:129
handle: <Handle Client.receive_loop.<locals>.after_interrupt(<Task cancell...nt_ws.py:312>>) at /home/ar1ess/projects/crypto/.venv/lib/python3.12/site-packages/ccxt/async_support/base/ws/client.py:129>
Traceback (most recent call last):
  File "/usr/lib/python3.12/asyncio/runners.py", line 194, in run
    return runner.run(main)
           ^^^^^^^^^^^^^^^^
  File "/usr/lib/python3.12/asyncio/runners.py", line 118, in run
    return self._loop.run_until_complete(task)
           ^^^^^^^^^^^^^^^^^^^^^^^^^^^^^^^^^^^
  File "/usr/lib/python3.12/asyncio/base_events.py", line 687, in run_until_complete
    return future.result()
           ^^^^^^^^^^^^^^^
  File "/home/ar1ess/projects/crypto/brain/main.py", line 372, in main
    await analyst.start_update()
  File "/home/ar1ess/projects/crypto/brain/Core/Analyst.py", line 231, in start_update
    async for update_coin in self.scout.coin_update():
  File "/home/ar1ess/projects/crypto/brain/Core/scouts/ScoutDad.py", line 19, in coin_update
    print(f"📥 ScoutDad: received from queue - {answer[0].name}: {answer[1].coin.name} = {answer[1].price:.6f}")
                                                                  ^^^^^^^^^^^^^^
AttributeError: 'Assets' object has no attribute 'coin'

During handling of the above exception, another exception occurred:

Traceback (most recent call last):
  File "/usr/lib/python3.12/asyncio/events.py", line 88, in _run
    self._context.run(self._callback, *self._args)
  File "/home/ar1ess/projects/crypto/.venv/lib/python3.12/site-packages/ccxt/async_support/base/ws/client.py", line 130, in after_interrupt
    exception = resolved.exception()
                ^^^^^^^^^^^^^^^^^^^^
  File "/home/ar1ess/projects/crypto/.venv/lib/python3.12/site-packages/aiohttp/client_ws.py", line 336, in receive
    msg = await self._reader.read()
          ^^^^^^^^^^^^^^^^^^^^^^^^^
  File "aiohttp/_websocket/reader_c.py", line 118, in read
  File "aiohttp/_websocket/reader_c.py", line 115, in aiohttp._websocket.reader_c.WebSocketDataQueue.read
asyncio.exceptions.CancelledError
2025-10-19 17:24:36,297 - asyncio - ERROR - Exception in callback Client.receive_loop.<locals>.after_interrupt(<Task cancell...nt_ws.py:312>>) at /home/ar1ess/projects/crypto/.venv/lib/python3.12/site-packages/ccxt/async_support/base/ws/client.py:129
handle: <Handle Client.receive_loop.<locals>.after_interrupt(<Task cancell...nt_ws.py:312>>) at /home/ar1ess/projects/crypto/.venv/lib/python3.12/site-packages/ccxt/async_support/base/ws/client.py:129>
Traceback (most recent call last):
  File "/usr/lib/python3.12/asyncio/runners.py", line 118, in run
    return self._loop.run_until_complete(task)
           ^^^^^^^^^^^^^^^^^^^^^^^^^^^^^^^^^^^
  File "/usr/lib/python3.12/asyncio/base_events.py", line 687, in run_until_complete
    return future.result()
           ^^^^^^^^^^^^^^^
  File "/home/ar1ess/projects/crypto/brain/main.py", line 372, in main
    await analyst.start_update()
  File "/home/ar1ess/projects/crypto/brain/Core/Analyst.py", line 231, in start_update
    async for update_coin in self.scout.coin_update():
  File "/home/ar1ess/projects/crypto/brain/Core/scouts/ScoutDad.py", line 18, in coin_update
    answer = await self.queue.get()
             ^^^^^^^^^^^^^^^^^^^^^^
  File "/usr/lib/python3.12/asyncio/queues.py", line 158, in get
    await getter
asyncio.exceptions.CancelledError

During handling of the above exception, another exception occurred:

Traceback (most recent call last):
  File "/usr/lib/python3.12/asyncio/runners.py", line 194, in run
    return runner.run(main)
           ^^^^^^^^^^^^^^^^
  File "/usr/lib/python3.12/asyncio/runners.py", line 123, in run
    raise KeyboardInterrupt()
KeyboardInterrupt

During handling of the above exception, another exception occurred:

Traceback (most recent call last):
  File "/usr/lib/python3.12/asyncio/events.py", line 88, in _run
    self._context.run(self._callback, *self._args)
  File "/home/ar1ess/projects/crypto/.venv/lib/python3.12/site-packages/ccxt/async_support/base/ws/client.py", line 130, in after_interrupt
    exception = resolved.exception()
                ^^^^^^^^^^^^^^^^^^^^
  File "/home/ar1ess/projects/crypto/.venv/lib/python3.12/site-packages/aiohttp/client_ws.py", line 336, in receive
    msg = await self._reader.read()
          ^^^^^^^^^^^^^^^^^^^^^^^^^
  File "aiohttp/_websocket/reader_c.py", line 118, in read
  File "aiohttp/_websocket/reader_c.py", line 115, in aiohttp._websocket.reader_c.WebSocketDataQueue.read
asyncio.exceptions.CancelledError
2025-10-19 17:24:36,304 - asyncio - ERROR - Exception in callback Future.race.<locals>.callback(<Task cancell...tasks.py:435>>) at /home/ar1ess/projects/crypto/.venv/lib/python3.12/site-packages/ccxt/async_support/base/ws/future.py:22
handle: <Handle Future.race.<locals>.callback(<Task cancell...tasks.py:435>>) at /home/ar1ess/projects/crypto/.venv/lib/python3.12/site-packages/ccxt/async_support/base/ws/future.py:22>
Traceback (most recent call last):
  File "/usr/lib/python3.12/asyncio/runners.py", line 118, in run
    return self._loop.run_until_complete(task)
           ^^^^^^^^^^^^^^^^^^^^^^^^^^^^^^^^^^^
  File "/usr/lib/python3.12/asyncio/base_events.py", line 687, in run_until_complete
    return future.result()
           ^^^^^^^^^^^^^^^
  File "/home/ar1ess/projects/crypto/brain/main.py", line 372, in main
    await analyst.start_update()
  File "/home/ar1ess/projects/crypto/brain/Core/Analyst.py", line 231, in start_update
    async for update_coin in self.scout.coin_update():
  File "/home/ar1ess/projects/crypto/brain/Core/scouts/ScoutDad.py", line 18, in coin_update
    answer = await self.queue.get()
             ^^^^^^^^^^^^^^^^^^^^^^
  File "/usr/lib/python3.12/asyncio/queues.py", line 158, in get
    await getter
asyncio.exceptions.CancelledError

During handling of the above exception, another exception occurred:

Traceback (most recent call last):
  File "/usr/lib/python3.12/asyncio/runners.py", line 194, in run
    return runner.run(main)
           ^^^^^^^^^^^^^^^^
  File "/usr/lib/python3.12/asyncio/runners.py", line 123, in run
    raise KeyboardInterrupt()
KeyboardInterrupt

During handling of the above exception, another exception occurred:

Traceback (most recent call last):
  File "/usr/lib/python3.12/asyncio/events.py", line 88, in _run
    self._context.run(self._callback, *self._args)
  File "/home/ar1ess/projects/crypto/.venv/lib/python3.12/site-packages/ccxt/async_support/base/ws/future.py", line 23, in callback
    complete, _ = done.result()
                  ^^^^^^^^^^^^^
  File "/usr/lib/python3.12/asyncio/tasks.py", line 464, in wait
    return await _wait(fs, timeout, return_when, loop)
           ^^^^^^^^^^^^^^^^^^^^^^^^^^^^^^^^^^^^^^^^^^^
  File "/usr/lib/python3.12/asyncio/tasks.py", line 550, in _wait
    await waiter
asyncio.exceptions.CancelledError
2025-10-19 17:24:36,306 - asyncio - ERROR - Exception in callback Client.receive_loop.<locals>.after_interrupt(<Task cancell...nt_ws.py:312>>) at /home/ar1ess/projects/crypto/.venv/lib/python3.12/site-packages/ccxt/async_support/base/ws/client.py:129
handle: <Handle Client.receive_loop.<locals>.after_interrupt(<Task cancell...nt_ws.py:312>>) at /home/ar1ess/projects/crypto/.venv/lib/python3.12/site-packages/ccxt/async_support/base/ws/client.py:129>
Traceback (most recent call last):
  File "/usr/lib/python3.12/asyncio/runners.py", line 118, in run
    return self._loop.run_until_complete(task)
           ^^^^^^^^^^^^^^^^^^^^^^^^^^^^^^^^^^^
  File "/usr/lib/python3.12/asyncio/base_events.py", line 687, in run_until_complete
    return future.result()
           ^^^^^^^^^^^^^^^
  File "/home/ar1ess/projects/crypto/brain/main.py", line 372, in main
    await analyst.start_update()
  File "/home/ar1ess/projects/crypto/brain/Core/Analyst.py", line 231, in start_update
    async for update_coin in self.scout.coin_update():
  File "/home/ar1ess/projects/crypto/brain/Core/scouts/ScoutDad.py", line 18, in coin_update
    answer = await self.queue.get()
             ^^^^^^^^^^^^^^^^^^^^^^
  File "/usr/lib/python3.12/asyncio/queues.py", line 158, in get
    await getter
asyncio.exceptions.CancelledError

During handling of the above exception, another exception occurred:

Traceback (most recent call last):
  File "/usr/lib/python3.12/asyncio/runners.py", line 194, in run
    return runner.run(main)
           ^^^^^^^^^^^^^^^^
  File "/usr/lib/python3.12/asyncio/runners.py", line 123, in run
    raise KeyboardInterrupt()
KeyboardInterrupt

During handling of the above exception, another exception occurred:

Traceback (most recent call last):
  File "/usr/lib/python3.12/asyncio/events.py", line 88, in _run
    self._context.run(self._callback, *self._args)
  File "/home/ar1ess/projects/crypto/.venv/lib/python3.12/site-packages/ccxt/async_support/base/ws/client.py", line 130, in after_interrupt
    exception = resolved.exception()
                ^^^^^^^^^^^^^^^^^^^^
  File "/home/ar1ess/projects/crypto/.venv/lib/python3.12/site-packages/aiohttp/client_ws.py", line 336, in receive
    msg = await self._reader.read()
          ^^^^^^^^^^^^^^^^^^^^^^^^^
  File "aiohttp/_websocket/reader_c.py", line 118, in read
  File "aiohttp/_websocket/reader_c.py", line 115, in aiohttp._websocket.reader_c.WebSocketDataQueue.read
asyncio.exceptions.CancelledError
2025-10-19 17:24:36,307 - asyncio - ERROR - Exception in callback Client.receive_loop.<locals>.after_interrupt(<Task cancell...nt_ws.py:312>>) at /home/ar1ess/projects/crypto/.venv/lib/python3.12/site-packages/ccxt/async_support/base/ws/client.py:129
handle: <Handle Client.receive_loop.<locals>.after_interrupt(<Task cancell...nt_ws.py:312>>) at /home/ar1ess/projects/crypto/.venv/lib/python3.12/site-packages/ccxt/async_support/base/ws/client.py:129>
Traceback (most recent call last):
  File "/usr/lib/python3.12/asyncio/runners.py", line 118, in run
    return self._loop.run_until_complete(task)
           ^^^^^^^^^^^^^^^^^^^^^^^^^^^^^^^^^^^
  File "/usr/lib/python3.12/asyncio/base_events.py", line 687, in run_until_complete
    return future.result()
           ^^^^^^^^^^^^^^^
  File "/home/ar1ess/projects/crypto/brain/main.py", line 372, in main
    await analyst.start_update()
  File "/home/ar1ess/projects/crypto/brain/Core/Analyst.py", line 231, in start_update
    async for update_coin in self.scout.coin_update():
  File "/home/ar1ess/projects/crypto/brain/Core/scouts/ScoutDad.py", line 18, in coin_update
    answer = await self.queue.get()
             ^^^^^^^^^^^^^^^^^^^^^^
  File "/usr/lib/python3.12/asyncio/queues.py", line 158, in get
    await getter
asyncio.exceptions.CancelledError

During handling of the above exception, another exception occurred:

Traceback (most recent call last):
  File "/usr/lib/python3.12/asyncio/runners.py", line 194, in run
    return runner.run(main)
           ^^^^^^^^^^^^^^^^
  File "/usr/lib/python3.12/asyncio/runners.py", line 123, in run
    raise KeyboardInterrupt()
KeyboardInterrupt

During handling of the above exception, another exception occurred:

Traceback (most recent call last):
  File "/usr/lib/python3.12/asyncio/events.py", line 88, in _run
    self._context.run(self._callback, *self._args)
  File "/home/ar1ess/projects/crypto/.venv/lib/python3.12/site-packages/ccxt/async_support/base/ws/client.py", line 130, in after_interrupt
    exception = resolved.exception()
                ^^^^^^^^^^^^^^^^^^^^
  File "/home/ar1ess/projects/crypto/.venv/lib/python3.12/site-packages/aiohttp/client_ws.py", line 336, in receive
    msg = await self._reader.read()
          ^^^^^^^^^^^^^^^^^^^^^^^^^
  File "aiohttp/_websocket/reader_c.py", line 118, in read
  File "aiohttp/_websocket/reader_c.py", line 115, in aiohttp._websocket.reader_c.WebSocketDataQueue.read
asyncio.exceptions.CancelledError
2025-10-19 17:24:36,307 - asyncio - ERROR - Exception in callback Future.race.<locals>.callback(<Task cancell...tasks.py:435>>) at /home/ar1ess/projects/crypto/.venv/lib/python3.12/site-packages/ccxt/async_support/base/ws/future.py:22
handle: <Handle Future.race.<locals>.callback(<Task cancell...tasks.py:435>>) at /home/ar1ess/projects/crypto/.venv/lib/python3.12/site-packages/ccxt/async_support/base/ws/future.py:22>
Traceback (most recent call last):
  File "/usr/lib/python3.12/asyncio/runners.py", line 118, in run
    return self._loop.run_until_complete(task)
           ^^^^^^^^^^^^^^^^^^^^^^^^^^^^^^^^^^^
  File "/usr/lib/python3.12/asyncio/base_events.py", line 687, in run_until_complete
    return future.result()
           ^^^^^^^^^^^^^^^
  File "/home/ar1ess/projects/crypto/brain/main.py", line 372, in main
    await analyst.start_update()
  File "/home/ar1ess/projects/crypto/brain/Core/Analyst.py", line 231, in start_update
    async for update_coin in self.scout.coin_update():
  File "/home/ar1ess/projects/crypto/brain/Core/scouts/ScoutDad.py", line 18, in coin_update
    answer = await self.queue.get()
             ^^^^^^^^^^^^^^^^^^^^^^
  File "/usr/lib/python3.12/asyncio/queues.py", line 158, in get
    await getter
asyncio.exceptions.CancelledError

During handling of the above exception, another exception occurred:

Traceback (most recent call last):
  File "/usr/lib/python3.12/asyncio/runners.py", line 194, in run
    return runner.run(main)
           ^^^^^^^^^^^^^^^^
  File "/usr/lib/python3.12/asyncio/runners.py", line 123, in run
    raise KeyboardInterrupt()
KeyboardInterrupt

During handling of the above exception, another exception occurred:

Traceback (most recent call last):
  File "/usr/lib/python3.12/asyncio/events.py", line 88, in _run
    self._context.run(self._callback, *self._args)
  File "/home/ar1ess/projects/crypto/.venv/lib/python3.12/site-packages/ccxt/async_support/base/ws/future.py", line 23, in callback
    complete, _ = done.result()
                  ^^^^^^^^^^^^^
  File "/usr/lib/python3.12/asyncio/tasks.py", line 464, in wait
    return await _wait(fs, timeout, return_when, loop)
           ^^^^^^^^^^^^^^^^^^^^^^^^^^^^^^^^^^^^^^^^^^^
  File "/usr/lib/python3.12/asyncio/tasks.py", line 550, in _wait
    await waiter
asyncio.exceptions.CancelledError
2025-10-19 17:24:36,308 - asyncio - ERROR - Exception in callback Future.race.<locals>.callback(<Task cancell...tasks.py:435>>) at /home/ar1ess/projects/crypto/.venv/lib/python3.12/site-packages/ccxt/async_support/base/ws/future.py:22
handle: <Handle Future.race.<locals>.callback(<Task cancell...tasks.py:435>>) at /home/ar1ess/projects/crypto/.venv/lib/python3.12/site-packages/ccxt/async_support/base/ws/future.py:22>
Traceback (most recent call last):
  File "/usr/lib/python3.12/asyncio/runners.py", line 118, in run
    return self._loop.run_until_complete(task)
           ^^^^^^^^^^^^^^^^^^^^^^^^^^^^^^^^^^^
  File "/usr/lib/python3.12/asyncio/base_events.py", line 687, in run_until_complete
    return future.result()
           ^^^^^^^^^^^^^^^
  File "/home/ar1ess/projects/crypto/brain/main.py", line 372, in main
    await analyst.start_update()
  File "/home/ar1ess/projects/crypto/brain/Core/Analyst.py", line 231, in start_update
    async for update_coin in self.scout.coin_update():
  File "/home/ar1ess/projects/crypto/brain/Core/scouts/ScoutDad.py", line 18, in coin_update
    answer = await self.queue.get()
             ^^^^^^^^^^^^^^^^^^^^^^
  File "/usr/lib/python3.12/asyncio/queues.py", line 158, in get
    await getter
asyncio.exceptions.CancelledError

During handling of the above exception, another exception occurred:

Traceback (most recent call last):
  File "/usr/lib/python3.12/asyncio/runners.py", line 194, in run
    return runner.run(main)
           ^^^^^^^^^^^^^^^^
  File "/usr/lib/python3.12/asyncio/runners.py", line 123, in run
    raise KeyboardInterrupt()
KeyboardInterrupt

During handling of the above exception, another exception occurred:

Traceback (most recent call last):
  File "/usr/lib/python3.12/asyncio/events.py", line 88, in _run
    self._context.run(self._callback, *self._args)
  File "/home/ar1ess/projects/crypto/.venv/lib/python3.12/site-packages/ccxt/async_support/base/ws/future.py", line 23, in callback
    complete, _ = done.result()
                  ^^^^^^^^^^^^^
  File "/usr/lib/python3.12/asyncio/tasks.py", line 464, in wait
    return await _wait(fs, timeout, return_when, loop)
           ^^^^^^^^^^^^^^^^^^^^^^^^^^^^^^^^^^^^^^^^^^^
  File "/usr/lib/python3.12/asyncio/tasks.py", line 550, in _wait
    await waiter
asyncio.exceptions.CancelledError
2025-10-19 17:24:36,308 - asyncio - ERROR - Exception in callback Client.receive_loop.<locals>.after_interrupt(<Task cancell...nt_ws.py:312>>) at /home/ar1ess/projects/crypto/.venv/lib/python3.12/site-packages/ccxt/async_support/base/ws/client.py:129
handle: <Handle Client.receive_loop.<locals>.after_interrupt(<Task cancell...nt_ws.py:312>>) at /home/ar1ess/projects/crypto/.venv/lib/python3.12/site-packages/ccxt/async_support/base/ws/client.py:129>
Traceback (most recent call last):
  File "/usr/lib/python3.12/asyncio/runners.py", line 118, in run
    return self._loop.run_until_complete(task)
           ^^^^^^^^^^^^^^^^^^^^^^^^^^^^^^^^^^^
  File "/usr/lib/python3.12/asyncio/base_events.py", line 687, in run_until_complete
    return future.result()
           ^^^^^^^^^^^^^^^
  File "/home/ar1ess/projects/crypto/brain/main.py", line 372, in main
    await analyst.start_update()
  File "/home/ar1ess/projects/crypto/brain/Core/Analyst.py", line 231, in start_update
    async for update_coin in self.scout.coin_update():
  File "/home/ar1ess/projects/crypto/brain/Core/scouts/ScoutDad.py", line 18, in coin_update
    answer = await self.queue.get()
             ^^^^^^^^^^^^^^^^^^^^^^
  File "/usr/lib/python3.12/asyncio/queues.py", line 158, in get
    await getter
asyncio.exceptions.CancelledError

During handling of the above exception, another exception occurred:

Traceback (most recent call last):
  File "/usr/lib/python3.12/asyncio/runners.py", line 194, in run
    return runner.run(main)
           ^^^^^^^^^^^^^^^^
  File "/usr/lib/python3.12/asyncio/runners.py", line 123, in run
    raise KeyboardInterrupt()
KeyboardInterrupt

During handling of the above exception, another exception occurred:

Traceback (most recent call last):
  File "/usr/lib/python3.12/asyncio/events.py", line 88, in _run
    self._context.run(self._callback, *self._args)
  File "/home/ar1ess/projects/crypto/.venv/lib/python3.12/site-packages/ccxt/async_support/base/ws/client.py", line 130, in after_interrupt
    exception = resolved.exception()
                ^^^^^^^^^^^^^^^^^^^^
  File "/home/ar1ess/projects/crypto/.venv/lib/python3.12/site-packages/aiohttp/client_ws.py", line 336, in receive
    msg = await self._reader.read()
          ^^^^^^^^^^^^^^^^^^^^^^^^^
  File "aiohttp/_websocket/reader_c.py", line 118, in read
  File "aiohttp/_websocket/reader_c.py", line 115, in aiohttp._websocket.reader_c.WebSocketDataQueue.read
asyncio.exceptions.CancelledError
2025-10-19 17:24:36,309 - asyncio - ERROR - Exception in callback Client.receive_loop.<locals>.after_interrupt(<Task cancell...nt_ws.py:312>>) at /home/ar1ess/projects/crypto/.venv/lib/python3.12/site-packages/ccxt/async_support/base/ws/client.py:129
handle: <Handle Client.receive_loop.<locals>.after_interrupt(<Task cancell...nt_ws.py:312>>) at /home/ar1ess/projects/crypto/.venv/lib/python3.12/site-packages/ccxt/async_support/base/ws/client.py:129>
Traceback (most recent call last):
  File "/usr/lib/python3.12/asyncio/runners.py", line 118, in run
    return self._loop.run_until_complete(task)
           ^^^^^^^^^^^^^^^^^^^^^^^^^^^^^^^^^^^
  File "/usr/lib/python3.12/asyncio/base_events.py", line 687, in run_until_complete
    return future.result()
           ^^^^^^^^^^^^^^^
  File "/home/ar1ess/projects/crypto/brain/main.py", line 372, in main
    await analyst.start_update()
  File "/home/ar1ess/projects/crypto/brain/Core/Analyst.py", line 231, in start_update
    async for update_coin in self.scout.coin_update():
  File "/home/ar1ess/projects/crypto/brain/Core/scouts/ScoutDad.py", line 18, in coin_update
    answer = await self.queue.get()
             ^^^^^^^^^^^^^^^^^^^^^^
  File "/usr/lib/python3.12/asyncio/queues.py", line 158, in get
    await getter
asyncio.exceptions.CancelledError

During handling of the above exception, another exception occurred:

Traceback (most recent call last):
  File "/usr/lib/python3.12/asyncio/runners.py", line 194, in run
    return runner.run(main)
           ^^^^^^^^^^^^^^^^
  File "/usr/lib/python3.12/asyncio/runners.py", line 123, in run
    raise KeyboardInterrupt()
KeyboardInterrupt

During handling of the above exception, another exception occurred:

Traceback (most recent call last):
  File "/usr/lib/python3.12/asyncio/events.py", line 88, in _run
    self._context.run(self._callback, *self._args)
  File "/home/ar1ess/projects/crypto/.venv/lib/python3.12/site-packages/ccxt/async_support/base/ws/client.py", line 130, in after_interrupt
    exception = resolved.exception()
                ^^^^^^^^^^^^^^^^^^^^
  File "/home/ar1ess/projects/crypto/.venv/lib/python3.12/site-packages/aiohttp/client_ws.py", line 336, in receive
    msg = await self._reader.read()
          ^^^^^^^^^^^^^^^^^^^^^^^^^
  File "aiohttp/_websocket/reader_c.py", line 118, in read
  File "aiohttp/_websocket/reader_c.py", line 115, in aiohttp._websocket.reader_c.WebSocketDataQueue.read
asyncio.exceptions.CancelledError
2025-10-19 17:24:36,309 - asyncio - ERROR - Exception in callback Future.race.<locals>.callback(<Task cancell...tasks.py:435>>) at /home/ar1ess/projects/crypto/.venv/lib/python3.12/site-packages/ccxt/async_support/base/ws/future.py:22
handle: <Handle Future.race.<locals>.callback(<Task cancell...tasks.py:435>>) at /home/ar1ess/projects/crypto/.venv/lib/python3.12/site-packages/ccxt/async_support/base/ws/future.py:22>
Traceback (most recent call last):
  File "/usr/lib/python3.12/asyncio/runners.py", line 118, in run
    return self._loop.run_until_complete(task)
           ^^^^^^^^^^^^^^^^^^^^^^^^^^^^^^^^^^^
  File "/usr/lib/python3.12/asyncio/base_events.py", line 687, in run_until_complete
    return future.result()
           ^^^^^^^^^^^^^^^
  File "/home/ar1ess/projects/crypto/brain/main.py", line 372, in main
    await analyst.start_update()
  File "/home/ar1ess/projects/crypto/brain/Core/Analyst.py", line 231, in start_update
    async for update_coin in self.scout.coin_update():
  File "/home/ar1ess/projects/crypto/brain/Core/scouts/ScoutDad.py", line 18, in coin_update
    answer = await self.queue.get()
             ^^^^^^^^^^^^^^^^^^^^^^
  File "/usr/lib/python3.12/asyncio/queues.py", line 158, in get
    await getter
asyncio.exceptions.CancelledError

During handling of the above exception, another exception occurred:

Traceback (most recent call last):
  File "/usr/lib/python3.12/asyncio/runners.py", line 194, in run
    return runner.run(main)
           ^^^^^^^^^^^^^^^^
  File "/usr/lib/python3.12/asyncio/runners.py", line 123, in run
    raise KeyboardInterrupt()
KeyboardInterrupt

During handling of the above exception, another exception occurred:

Traceback (most recent call last):
  File "/usr/lib/python3.12/asyncio/events.py", line 88, in _run
    self._context.run(self._callback, *self._args)
  File "/home/ar1ess/projects/crypto/.venv/lib/python3.12/site-packages/ccxt/async_support/base/ws/future.py", line 23, in callback
    complete, _ = done.result()
                  ^^^^^^^^^^^^^
  File "/usr/lib/python3.12/asyncio/tasks.py", line 464, in wait
    return await _wait(fs, timeout, return_when, loop)
           ^^^^^^^^^^^^^^^^^^^^^^^^^^^^^^^^^^^^^^^^^^^
  File "/usr/lib/python3.12/asyncio/tasks.py", line 550, in _wait
    await waiter
asyncio.exceptions.CancelledError
2025-10-19 17:24:36,310 - asyncio - ERROR - Exception in callback Future.race.<locals>.callback(<Task cancell...tasks.py:435>>) at /home/ar1ess/projects/crypto/.venv/lib/python3.12/site-packages/ccxt/async_support/base/ws/future.py:22
handle: <Handle Future.race.<locals>.callback(<Task cancell...tasks.py:435>>) at /home/ar1ess/projects/crypto/.venv/lib/python3.12/site-packages/ccxt/async_support/base/ws/future.py:22>
Traceback (most recent call last):
  File "/usr/lib/python3.12/asyncio/runners.py", line 118, in run
    return self._loop.run_until_complete(task)
           ^^^^^^^^^^^^^^^^^^^^^^^^^^^^^^^^^^^
  File "/usr/lib/python3.12/asyncio/base_events.py", line 687, in run_until_complete
    return future.result()
           ^^^^^^^^^^^^^^^
  File "/home/ar1ess/projects/crypto/brain/main.py", line 372, in main
    await analyst.start_update()
  File "/home/ar1ess/projects/crypto/brain/Core/Analyst.py", line 231, in start_update
    async for update_coin in self.scout.coin_update():
  File "/home/ar1ess/projects/crypto/brain/Core/scouts/ScoutDad.py", line 18, in coin_update
    answer = await self.queue.get()
             ^^^^^^^^^^^^^^^^^^^^^^
  File "/usr/lib/python3.12/asyncio/queues.py", line 158, in get
    await getter
asyncio.exceptions.CancelledError

During handling of the above exception, another exception occurred:

Traceback (most recent call last):
  File "/usr/lib/python3.12/asyncio/runners.py", line 194, in run
    return runner.run(main)
           ^^^^^^^^^^^^^^^^
  File "/usr/lib/python3.12/asyncio/runners.py", line 123, in run
    raise KeyboardInterrupt()
KeyboardInterrupt

During handling of the above exception, another exception occurred:

Traceback (most recent call last):
  File "/usr/lib/python3.12/asyncio/events.py", line 88, in _run
    self._context.run(self._callback, *self._args)
  File "/home/ar1ess/projects/crypto/.venv/lib/python3.12/site-packages/ccxt/async_support/base/ws/future.py", line 23, in callback
    complete, _ = done.result()
                  ^^^^^^^^^^^^^
  File "/usr/lib/python3.12/asyncio/tasks.py", line 464, in wait
    return await _wait(fs, timeout, return_when, loop)
           ^^^^^^^^^^^^^^^^^^^^^^^^^^^^^^^^^^^^^^^^^^^
  File "/usr/lib/python3.12/asyncio/tasks.py", line 550, in _wait
    await waiter
asyncio.exceptions.CancelledError
2025-10-19 17:32:16,219 - asyncio - ERROR - Exception in callback Client.receive_loop.<locals>.after_interrupt(<Task cancell...nt_ws.py:312>>) at /home/ar1ess/projects/crypto/.venv/lib/python3.12/site-packages/ccxt/async_support/base/ws/client.py:129
handle: <Handle Client.receive_loop.<locals>.after_interrupt(<Task cancell...nt_ws.py:312>>) at /home/ar1ess/projects/crypto/.venv/lib/python3.12/site-packages/ccxt/async_support/base/ws/client.py:129>
Traceback (most recent call last):
  File "/usr/lib/python3.12/asyncio/runners.py", line 118, in run
    return self._loop.run_until_complete(task)
           ^^^^^^^^^^^^^^^^^^^^^^^^^^^^^^^^^^^
  File "/usr/lib/python3.12/asyncio/base_events.py", line 687, in run_until_complete
    return future.result()
           ^^^^^^^^^^^^^^^
  File "/home/ar1ess/projects/crypto/brain/main.py", line 372, in main
    await analyst.start_update()
  File "/home/ar1ess/projects/crypto/brain/Core/Analyst.py", line 231, in start_update
    async for update_coin in self.scout.coin_update():
  File "/home/ar1ess/projects/crypto/brain/Core/scouts/ScoutDad.py", line 18, in coin_update
    answer = await self.queue.get()
             ^^^^^^^^^^^^^^^^^^^^^^
  File "/usr/lib/python3.12/asyncio/queues.py", line 158, in get
    await getter
asyncio.exceptions.CancelledError

During handling of the above exception, another exception occurred:

Traceback (most recent call last):
  File "/usr/lib/python3.12/asyncio/runners.py", line 194, in run
    return runner.run(main)
           ^^^^^^^^^^^^^^^^
  File "/usr/lib/python3.12/asyncio/runners.py", line 123, in run
    raise KeyboardInterrupt()
KeyboardInterrupt

During handling of the above exception, another exception occurred:

Traceback (most recent call last):
  File "/usr/lib/python3.12/asyncio/events.py", line 88, in _run
    self._context.run(self._callback, *self._args)
  File "/home/ar1ess/projects/crypto/.venv/lib/python3.12/site-packages/ccxt/async_support/base/ws/client.py", line 130, in after_interrupt
    exception = resolved.exception()
                ^^^^^^^^^^^^^^^^^^^^
  File "/home/ar1ess/projects/crypto/.venv/lib/python3.12/site-packages/aiohttp/client_ws.py", line 336, in receive
    msg = await self._reader.read()
          ^^^^^^^^^^^^^^^^^^^^^^^^^
  File "aiohttp/_websocket/reader_c.py", line 118, in read
  File "aiohttp/_websocket/reader_c.py", line 115, in aiohttp._websocket.reader_c.WebSocketDataQueue.read
asyncio.exceptions.CancelledError
2025-10-19 17:32:16,226 - asyncio - ERROR - Exception in callback Future.race.<locals>.callback(<Task cancell...tasks.py:435>>) at /home/ar1ess/projects/crypto/.venv/lib/python3.12/site-packages/ccxt/async_support/base/ws/future.py:22
handle: <Handle Future.race.<locals>.callback(<Task cancell...tasks.py:435>>) at /home/ar1ess/projects/crypto/.venv/lib/python3.12/site-packages/ccxt/async_support/base/ws/future.py:22>
Traceback (most recent call last):
  File "/usr/lib/python3.12/asyncio/runners.py", line 118, in run
    return self._loop.run_until_complete(task)
           ^^^^^^^^^^^^^^^^^^^^^^^^^^^^^^^^^^^
  File "/usr/lib/python3.12/asyncio/base_events.py", line 687, in run_until_complete
    return future.result()
           ^^^^^^^^^^^^^^^
  File "/home/ar1ess/projects/crypto/brain/main.py", line 372, in main
    await analyst.start_update()
  File "/home/ar1ess/projects/crypto/brain/Core/Analyst.py", line 231, in start_update
    async for update_coin in self.scout.coin_update():
  File "/home/ar1ess/projects/crypto/brain/Core/scouts/ScoutDad.py", line 18, in coin_update
    answer = await self.queue.get()
             ^^^^^^^^^^^^^^^^^^^^^^
  File "/usr/lib/python3.12/asyncio/queues.py", line 158, in get
    await getter
asyncio.exceptions.CancelledError

During handling of the above exception, another exception occurred:

Traceback (most recent call last):
  File "/usr/lib/python3.12/asyncio/runners.py", line 194, in run
    return runner.run(main)
           ^^^^^^^^^^^^^^^^
  File "/usr/lib/python3.12/asyncio/runners.py", line 123, in run
    raise KeyboardInterrupt()
KeyboardInterrupt

During handling of the above exception, another exception occurred:

Traceback (most recent call last):
  File "/usr/lib/python3.12/asyncio/events.py", line 88, in _run
    self._context.run(self._callback, *self._args)
  File "/home/ar1ess/projects/crypto/.venv/lib/python3.12/site-packages/ccxt/async_support/base/ws/future.py", line 23, in callback
    complete, _ = done.result()
                  ^^^^^^^^^^^^^
  File "/usr/lib/python3.12/asyncio/tasks.py", line 464, in wait
    return await _wait(fs, timeout, return_when, loop)
           ^^^^^^^^^^^^^^^^^^^^^^^^^^^^^^^^^^^^^^^^^^^
  File "/usr/lib/python3.12/asyncio/tasks.py", line 550, in _wait
    await waiter
asyncio.exceptions.CancelledError
2025-10-19 17:32:16,228 - asyncio - ERROR - Exception in callback Future.race.<locals>.callback(<Task cancell...tasks.py:435>>) at /home/ar1ess/projects/crypto/.venv/lib/python3.12/site-packages/ccxt/async_support/base/ws/future.py:22
handle: <Handle Future.race.<locals>.callback(<Task cancell...tasks.py:435>>) at /home/ar1ess/projects/crypto/.venv/lib/python3.12/site-packages/ccxt/async_support/base/ws/future.py:22>
Traceback (most recent call last):
  File "/usr/lib/python3.12/asyncio/runners.py", line 118, in run
    return self._loop.run_until_complete(task)
           ^^^^^^^^^^^^^^^^^^^^^^^^^^^^^^^^^^^
  File "/usr/lib/python3.12/asyncio/base_events.py", line 687, in run_until_complete
    return future.result()
           ^^^^^^^^^^^^^^^
  File "/home/ar1ess/projects/crypto/brain/main.py", line 372, in main
    await analyst.start_update()
  File "/home/ar1ess/projects/crypto/brain/Core/Analyst.py", line 231, in start_update
    async for update_coin in self.scout.coin_update():
  File "/home/ar1ess/projects/crypto/brain/Core/scouts/ScoutDad.py", line 18, in coin_update
    answer = await self.queue.get()
             ^^^^^^^^^^^^^^^^^^^^^^
  File "/usr/lib/python3.12/asyncio/queues.py", line 158, in get
    await getter
asyncio.exceptions.CancelledError

During handling of the above exception, another exception occurred:

Traceback (most recent call last):
  File "/usr/lib/python3.12/asyncio/runners.py", line 194, in run
    return runner.run(main)
           ^^^^^^^^^^^^^^^^
  File "/usr/lib/python3.12/asyncio/runners.py", line 123, in run
    raise KeyboardInterrupt()
KeyboardInterrupt

During handling of the above exception, another exception occurred:

Traceback (most recent call last):
  File "/usr/lib/python3.12/asyncio/events.py", line 88, in _run
    self._context.run(self._callback, *self._args)
  File "/home/ar1ess/projects/crypto/.venv/lib/python3.12/site-packages/ccxt/async_support/base/ws/future.py", line 23, in callback
    complete, _ = done.result()
                  ^^^^^^^^^^^^^
  File "/usr/lib/python3.12/asyncio/tasks.py", line 464, in wait
    return await _wait(fs, timeout, return_when, loop)
           ^^^^^^^^^^^^^^^^^^^^^^^^^^^^^^^^^^^^^^^^^^^
  File "/usr/lib/python3.12/asyncio/tasks.py", line 550, in _wait
    await waiter
asyncio.exceptions.CancelledError
2025-10-19 17:32:16,229 - asyncio - ERROR - Exception in callback Client.receive_loop.<locals>.after_interrupt(<Task cancell...nt_ws.py:312>>) at /home/ar1ess/projects/crypto/.venv/lib/python3.12/site-packages/ccxt/async_support/base/ws/client.py:129
handle: <Handle Client.receive_loop.<locals>.after_interrupt(<Task cancell...nt_ws.py:312>>) at /home/ar1ess/projects/crypto/.venv/lib/python3.12/site-packages/ccxt/async_support/base/ws/client.py:129>
Traceback (most recent call last):
  File "/usr/lib/python3.12/asyncio/runners.py", line 118, in run
    return self._loop.run_until_complete(task)
           ^^^^^^^^^^^^^^^^^^^^^^^^^^^^^^^^^^^
  File "/usr/lib/python3.12/asyncio/base_events.py", line 687, in run_until_complete
    return future.result()
           ^^^^^^^^^^^^^^^
  File "/home/ar1ess/projects/crypto/brain/main.py", line 372, in main
    await analyst.start_update()
  File "/home/ar1ess/projects/crypto/brain/Core/Analyst.py", line 231, in start_update
    async for update_coin in self.scout.coin_update():
  File "/home/ar1ess/projects/crypto/brain/Core/scouts/ScoutDad.py", line 18, in coin_update
    answer = await self.queue.get()
             ^^^^^^^^^^^^^^^^^^^^^^
  File "/usr/lib/python3.12/asyncio/queues.py", line 158, in get
    await getter
asyncio.exceptions.CancelledError

During handling of the above exception, another exception occurred:

Traceback (most recent call last):
  File "/usr/lib/python3.12/asyncio/runners.py", line 194, in run
    return runner.run(main)
           ^^^^^^^^^^^^^^^^
  File "/usr/lib/python3.12/asyncio/runners.py", line 123, in run
    raise KeyboardInterrupt()
KeyboardInterrupt

During handling of the above exception, another exception occurred:

Traceback (most recent call last):
  File "/usr/lib/python3.12/asyncio/events.py", line 88, in _run
    self._context.run(self._callback, *self._args)
  File "/home/ar1ess/projects/crypto/.venv/lib/python3.12/site-packages/ccxt/async_support/base/ws/client.py", line 130, in after_interrupt
    exception = resolved.exception()
                ^^^^^^^^^^^^^^^^^^^^
  File "/home/ar1ess/projects/crypto/.venv/lib/python3.12/site-packages/aiohttp/client_ws.py", line 336, in receive
    msg = await self._reader.read()
          ^^^^^^^^^^^^^^^^^^^^^^^^^
  File "aiohttp/_websocket/reader_c.py", line 118, in read
  File "aiohttp/_websocket/reader_c.py", line 115, in aiohttp._websocket.reader_c.WebSocketDataQueue.read
asyncio.exceptions.CancelledError
2025-10-19 17:32:16,229 - asyncio - ERROR - Exception in callback Client.receive_loop.<locals>.after_interrupt(<Task cancell...nt_ws.py:312>>) at /home/ar1ess/projects/crypto/.venv/lib/python3.12/site-packages/ccxt/async_support/base/ws/client.py:129
handle: <Handle Client.receive_loop.<locals>.after_interrupt(<Task cancell...nt_ws.py:312>>) at /home/ar1ess/projects/crypto/.venv/lib/python3.12/site-packages/ccxt/async_support/base/ws/client.py:129>
Traceback (most recent call last):
  File "/usr/lib/python3.12/asyncio/runners.py", line 118, in run
    return self._loop.run_until_complete(task)
           ^^^^^^^^^^^^^^^^^^^^^^^^^^^^^^^^^^^
  File "/usr/lib/python3.12/asyncio/base_events.py", line 687, in run_until_complete
    return future.result()
           ^^^^^^^^^^^^^^^
  File "/home/ar1ess/projects/crypto/brain/main.py", line 372, in main
    await analyst.start_update()
  File "/home/ar1ess/projects/crypto/brain/Core/Analyst.py", line 231, in start_update
    async for update_coin in self.scout.coin_update():
  File "/home/ar1ess/projects/crypto/brain/Core/scouts/ScoutDad.py", line 18, in coin_update
    answer = await self.queue.get()
             ^^^^^^^^^^^^^^^^^^^^^^
  File "/usr/lib/python3.12/asyncio/queues.py", line 158, in get
    await getter
asyncio.exceptions.CancelledError

During handling of the above exception, another exception occurred:

Traceback (most recent call last):
  File "/usr/lib/python3.12/asyncio/runners.py", line 194, in run
    return runner.run(main)
           ^^^^^^^^^^^^^^^^
  File "/usr/lib/python3.12/asyncio/runners.py", line 123, in run
    raise KeyboardInterrupt()
KeyboardInterrupt

During handling of the above exception, another exception occurred:

Traceback (most recent call last):
  File "/usr/lib/python3.12/asyncio/events.py", line 88, in _run
    self._context.run(self._callback, *self._args)
  File "/home/ar1ess/projects/crypto/.venv/lib/python3.12/site-packages/ccxt/async_support/base/ws/client.py", line 130, in after_interrupt
    exception = resolved.exception()
                ^^^^^^^^^^^^^^^^^^^^
  File "/home/ar1ess/projects/crypto/.venv/lib/python3.12/site-packages/aiohttp/client_ws.py", line 336, in receive
    msg = await self._reader.read()
          ^^^^^^^^^^^^^^^^^^^^^^^^^
  File "aiohttp/_websocket/reader_c.py", line 118, in read
  File "aiohttp/_websocket/reader_c.py", line 115, in aiohttp._websocket.reader_c.WebSocketDataQueue.read
asyncio.exceptions.CancelledError
2025-10-19 17:32:16,230 - asyncio - ERROR - Exception in callback Future.race.<locals>.callback(<Task cancell...tasks.py:435>>) at /home/ar1ess/projects/crypto/.venv/lib/python3.12/site-packages/ccxt/async_support/base/ws/future.py:22
handle: <Handle Future.race.<locals>.callback(<Task cancell...tasks.py:435>>) at /home/ar1ess/projects/crypto/.venv/lib/python3.12/site-packages/ccxt/async_support/base/ws/future.py:22>
Traceback (most recent call last):
  File "/usr/lib/python3.12/asyncio/runners.py", line 118, in run
    return self._loop.run_until_complete(task)
           ^^^^^^^^^^^^^^^^^^^^^^^^^^^^^^^^^^^
  File "/usr/lib/python3.12/asyncio/base_events.py", line 687, in run_until_complete
    return future.result()
           ^^^^^^^^^^^^^^^
  File "/home/ar1ess/projects/crypto/brain/main.py", line 372, in main
    await analyst.start_update()
  File "/home/ar1ess/projects/crypto/brain/Core/Analyst.py", line 231, in start_update
    async for update_coin in self.scout.coin_update():
  File "/home/ar1ess/projects/crypto/brain/Core/scouts/ScoutDad.py", line 18, in coin_update
    answer = await self.queue.get()
             ^^^^^^^^^^^^^^^^^^^^^^
  File "/usr/lib/python3.12/asyncio/queues.py", line 158, in get
    await getter
asyncio.exceptions.CancelledError

During handling of the above exception, another exception occurred:

Traceback (most recent call last):
  File "/usr/lib/python3.12/asyncio/runners.py", line 194, in run
    return runner.run(main)
           ^^^^^^^^^^^^^^^^
  File "/usr/lib/python3.12/asyncio/runners.py", line 123, in run
    raise KeyboardInterrupt()
KeyboardInterrupt

During handling of the above exception, another exception occurred:

Traceback (most recent call last):
  File "/usr/lib/python3.12/asyncio/events.py", line 88, in _run
    self._context.run(self._callback, *self._args)
  File "/home/ar1ess/projects/crypto/.venv/lib/python3.12/site-packages/ccxt/async_support/base/ws/future.py", line 23, in callback
    complete, _ = done.result()
                  ^^^^^^^^^^^^^
  File "/usr/lib/python3.12/asyncio/tasks.py", line 464, in wait
    return await _wait(fs, timeout, return_when, loop)
           ^^^^^^^^^^^^^^^^^^^^^^^^^^^^^^^^^^^^^^^^^^^
  File "/usr/lib/python3.12/asyncio/tasks.py", line 550, in _wait
    await waiter
asyncio.exceptions.CancelledError
2025-10-19 17:32:16,230 - asyncio - ERROR - Exception in callback Future.race.<locals>.callback(<Task cancell...tasks.py:435>>) at /home/ar1ess/projects/crypto/.venv/lib/python3.12/site-packages/ccxt/async_support/base/ws/future.py:22
handle: <Handle Future.race.<locals>.callback(<Task cancell...tasks.py:435>>) at /home/ar1ess/projects/crypto/.venv/lib/python3.12/site-packages/ccxt/async_support/base/ws/future.py:22>
Traceback (most recent call last):
  File "/usr/lib/python3.12/asyncio/runners.py", line 118, in run
    return self._loop.run_until_complete(task)
           ^^^^^^^^^^^^^^^^^^^^^^^^^^^^^^^^^^^
  File "/usr/lib/python3.12/asyncio/base_events.py", line 687, in run_until_complete
    return future.result()
           ^^^^^^^^^^^^^^^
  File "/home/ar1ess/projects/crypto/brain/main.py", line 372, in main
    await analyst.start_update()
  File "/home/ar1ess/projects/crypto/brain/Core/Analyst.py", line 231, in start_update
    async for update_coin in self.scout.coin_update():
  File "/home/ar1ess/projects/crypto/brain/Core/scouts/ScoutDad.py", line 18, in coin_update
    answer = await self.queue.get()
             ^^^^^^^^^^^^^^^^^^^^^^
  File "/usr/lib/python3.12/asyncio/queues.py", line 158, in get
    await getter
asyncio.exceptions.CancelledError

During handling of the above exception, another exception occurred:

Traceback (most recent call last):
  File "/usr/lib/python3.12/asyncio/runners.py", line 194, in run
    return runner.run(main)
           ^^^^^^^^^^^^^^^^
  File "/usr/lib/python3.12/asyncio/runners.py", line 123, in run
    raise KeyboardInterrupt()
KeyboardInterrupt

During handling of the above exception, another exception occurred:

Traceback (most recent call last):
  File "/usr/lib/python3.12/asyncio/events.py", line 88, in _run
    self._context.run(self._callback, *self._args)
  File "/home/ar1ess/projects/crypto/.venv/lib/python3.12/site-packages/ccxt/async_support/base/ws/future.py", line 23, in callback
    complete, _ = done.result()
                  ^^^^^^^^^^^^^
  File "/usr/lib/python3.12/asyncio/tasks.py", line 464, in wait
    return await _wait(fs, timeout, return_when, loop)
           ^^^^^^^^^^^^^^^^^^^^^^^^^^^^^^^^^^^^^^^^^^^
  File "/usr/lib/python3.12/asyncio/tasks.py", line 550, in _wait
    await waiter
asyncio.exceptions.CancelledError
2025-10-19 17:32:16,231 - asyncio - ERROR - Exception in callback Client.receive_loop.<locals>.after_interrupt(<Task cancell...nt_ws.py:312>>) at /home/ar1ess/projects/crypto/.venv/lib/python3.12/site-packages/ccxt/async_support/base/ws/client.py:129
handle: <Handle Client.receive_loop.<locals>.after_interrupt(<Task cancell...nt_ws.py:312>>) at /home/ar1ess/projects/crypto/.venv/lib/python3.12/site-packages/ccxt/async_support/base/ws/client.py:129>
Traceback (most recent call last):
  File "/usr/lib/python3.12/asyncio/runners.py", line 118, in run
    return self._loop.run_until_complete(task)
           ^^^^^^^^^^^^^^^^^^^^^^^^^^^^^^^^^^^
  File "/usr/lib/python3.12/asyncio/base_events.py", line 687, in run_until_complete
    return future.result()
           ^^^^^^^^^^^^^^^
  File "/home/ar1ess/projects/crypto/brain/main.py", line 372, in main
    await analyst.start_update()
  File "/home/ar1ess/projects/crypto/brain/Core/Analyst.py", line 231, in start_update
    async for update_coin in self.scout.coin_update():
  File "/home/ar1ess/projects/crypto/brain/Core/scouts/ScoutDad.py", line 18, in coin_update
    answer = await self.queue.get()
             ^^^^^^^^^^^^^^^^^^^^^^
  File "/usr/lib/python3.12/asyncio/queues.py", line 158, in get
    await getter
asyncio.exceptions.CancelledError

During handling of the above exception, another exception occurred:

Traceback (most recent call last):
  File "/usr/lib/python3.12/asyncio/runners.py", line 194, in run
    return runner.run(main)
           ^^^^^^^^^^^^^^^^
  File "/usr/lib/python3.12/asyncio/runners.py", line 123, in run
    raise KeyboardInterrupt()
KeyboardInterrupt

During handling of the above exception, another exception occurred:

Traceback (most recent call last):
  File "/usr/lib/python3.12/asyncio/events.py", line 88, in _run
    self._context.run(self._callback, *self._args)
  File "/home/ar1ess/projects/crypto/.venv/lib/python3.12/site-packages/ccxt/async_support/base/ws/client.py", line 130, in after_interrupt
    exception = resolved.exception()
                ^^^^^^^^^^^^^^^^^^^^
  File "/home/ar1ess/projects/crypto/.venv/lib/python3.12/site-packages/aiohttp/client_ws.py", line 336, in receive
    msg = await self._reader.read()
          ^^^^^^^^^^^^^^^^^^^^^^^^^
  File "aiohttp/_websocket/reader_c.py", line 118, in read
  File "aiohttp/_websocket/reader_c.py", line 115, in aiohttp._websocket.reader_c.WebSocketDataQueue.read
asyncio.exceptions.CancelledError
2025-10-19 17:32:16,231 - asyncio - ERROR - Exception in callback Future.race.<locals>.callback(<Task cancell...tasks.py:435>>) at /home/ar1ess/projects/crypto/.venv/lib/python3.12/site-packages/ccxt/async_support/base/ws/future.py:22
handle: <Handle Future.race.<locals>.callback(<Task cancell...tasks.py:435>>) at /home/ar1ess/projects/crypto/.venv/lib/python3.12/site-packages/ccxt/async_support/base/ws/future.py:22>
Traceback (most recent call last):
  File "/usr/lib/python3.12/asyncio/runners.py", line 118, in run
    return self._loop.run_until_complete(task)
           ^^^^^^^^^^^^^^^^^^^^^^^^^^^^^^^^^^^
  File "/usr/lib/python3.12/asyncio/base_events.py", line 687, in run_until_complete
    return future.result()
           ^^^^^^^^^^^^^^^
  File "/home/ar1ess/projects/crypto/brain/main.py", line 372, in main
    await analyst.start_update()
  File "/home/ar1ess/projects/crypto/brain/Core/Analyst.py", line 231, in start_update
    async for update_coin in self.scout.coin_update():
  File "/home/ar1ess/projects/crypto/brain/Core/scouts/ScoutDad.py", line 18, in coin_update
    answer = await self.queue.get()
             ^^^^^^^^^^^^^^^^^^^^^^
  File "/usr/lib/python3.12/asyncio/queues.py", line 158, in get
    await getter
asyncio.exceptions.CancelledError

During handling of the above exception, another exception occurred:

Traceback (most recent call last):
  File "/usr/lib/python3.12/asyncio/runners.py", line 194, in run
    return runner.run(main)
           ^^^^^^^^^^^^^^^^
  File "/usr/lib/python3.12/asyncio/runners.py", line 123, in run
    raise KeyboardInterrupt()
KeyboardInterrupt

During handling of the above exception, another exception occurred:

Traceback (most recent call last):
  File "/usr/lib/python3.12/asyncio/events.py", line 88, in _run
    self._context.run(self._callback, *self._args)
  File "/home/ar1ess/projects/crypto/.venv/lib/python3.12/site-packages/ccxt/async_support/base/ws/future.py", line 23, in callback
    complete, _ = done.result()
                  ^^^^^^^^^^^^^
  File "/usr/lib/python3.12/asyncio/tasks.py", line 464, in wait
    return await _wait(fs, timeout, return_when, loop)
           ^^^^^^^^^^^^^^^^^^^^^^^^^^^^^^^^^^^^^^^^^^^
  File "/usr/lib/python3.12/asyncio/tasks.py", line 550, in _wait
    await waiter
asyncio.exceptions.CancelledError
2025-10-19 17:32:16,232 - asyncio - ERROR - Exception in callback Client.receive_loop.<locals>.after_interrupt(<Task cancell...nt_ws.py:312>>) at /home/ar1ess/projects/crypto/.venv/lib/python3.12/site-packages/ccxt/async_support/base/ws/client.py:129
handle: <Handle Client.receive_loop.<locals>.after_interrupt(<Task cancell...nt_ws.py:312>>) at /home/ar1ess/projects/crypto/.venv/lib/python3.12/site-packages/ccxt/async_support/base/ws/client.py:129>
Traceback (most recent call last):
  File "/usr/lib/python3.12/asyncio/runners.py", line 118, in run
    return self._loop.run_until_complete(task)
           ^^^^^^^^^^^^^^^^^^^^^^^^^^^^^^^^^^^
  File "/usr/lib/python3.12/asyncio/base_events.py", line 687, in run_until_complete
    return future.result()
           ^^^^^^^^^^^^^^^
  File "/home/ar1ess/projects/crypto/brain/main.py", line 372, in main
    await analyst.start_update()
  File "/home/ar1ess/projects/crypto/brain/Core/Analyst.py", line 231, in start_update
    async for update_coin in self.scout.coin_update():
  File "/home/ar1ess/projects/crypto/brain/Core/scouts/ScoutDad.py", line 18, in coin_update
    answer = await self.queue.get()
             ^^^^^^^^^^^^^^^^^^^^^^
  File "/usr/lib/python3.12/asyncio/queues.py", line 158, in get
    await getter
asyncio.exceptions.CancelledError

During handling of the above exception, another exception occurred:

Traceback (most recent call last):
  File "/usr/lib/python3.12/asyncio/runners.py", line 194, in run
    return runner.run(main)
           ^^^^^^^^^^^^^^^^
  File "/usr/lib/python3.12/asyncio/runners.py", line 123, in run
    raise KeyboardInterrupt()
KeyboardInterrupt

During handling of the above exception, another exception occurred:

Traceback (most recent call last):
  File "/usr/lib/python3.12/asyncio/events.py", line 88, in _run
    self._context.run(self._callback, *self._args)
  File "/home/ar1ess/projects/crypto/.venv/lib/python3.12/site-packages/ccxt/async_support/base/ws/client.py", line 130, in after_interrupt
    exception = resolved.exception()
                ^^^^^^^^^^^^^^^^^^^^
  File "/home/ar1ess/projects/crypto/.venv/lib/python3.12/site-packages/aiohttp/client_ws.py", line 336, in receive
    msg = await self._reader.read()
          ^^^^^^^^^^^^^^^^^^^^^^^^^
  File "aiohttp/_websocket/reader_c.py", line 118, in read
  File "aiohttp/_websocket/reader_c.py", line 115, in aiohttp._websocket.reader_c.WebSocketDataQueue.read
asyncio.exceptions.CancelledError
2025-10-19 17:33:54,036 - asyncio - ERROR - Exception in callback Client.receive_loop.<locals>.after_interrupt(<Task cancell...nt_ws.py:312>>) at /home/ar1ess/projects/crypto/.venv/lib/python3.12/site-packages/ccxt/async_support/base/ws/client.py:129
handle: <Handle Client.receive_loop.<locals>.after_interrupt(<Task cancell...nt_ws.py:312>>) at /home/ar1ess/projects/crypto/.venv/lib/python3.12/site-packages/ccxt/async_support/base/ws/client.py:129>
Traceback (most recent call last):
  File "/usr/lib/python3.12/asyncio/runners.py", line 118, in run
    return self._loop.run_until_complete(task)
           ^^^^^^^^^^^^^^^^^^^^^^^^^^^^^^^^^^^
  File "/usr/lib/python3.12/asyncio/base_events.py", line 687, in run_until_complete
    return future.result()
           ^^^^^^^^^^^^^^^
  File "/home/ar1ess/projects/crypto/brain/main.py", line 372, in main
    await analyst.start_update()
  File "/home/ar1ess/projects/crypto/brain/Core/Analyst.py", line 231, in start_update
    async for update_coin in self.scout.coin_update():
  File "/home/ar1ess/projects/crypto/brain/Core/scouts/ScoutDad.py", line 18, in coin_update
    answer = await self.queue.get()
             ^^^^^^^^^^^^^^^^^^^^^^
  File "/usr/lib/python3.12/asyncio/queues.py", line 158, in get
    await getter
asyncio.exceptions.CancelledError

During handling of the above exception, another exception occurred:

Traceback (most recent call last):
  File "/usr/lib/python3.12/asyncio/runners.py", line 194, in run
    return runner.run(main)
           ^^^^^^^^^^^^^^^^
  File "/usr/lib/python3.12/asyncio/runners.py", line 123, in run
    raise KeyboardInterrupt()
KeyboardInterrupt

During handling of the above exception, another exception occurred:

Traceback (most recent call last):
  File "/usr/lib/python3.12/asyncio/events.py", line 88, in _run
    self._context.run(self._callback, *self._args)
  File "/home/ar1ess/projects/crypto/.venv/lib/python3.12/site-packages/ccxt/async_support/base/ws/client.py", line 130, in after_interrupt
    exception = resolved.exception()
                ^^^^^^^^^^^^^^^^^^^^
  File "/home/ar1ess/projects/crypto/.venv/lib/python3.12/site-packages/aiohttp/client_ws.py", line 336, in receive
    msg = await self._reader.read()
          ^^^^^^^^^^^^^^^^^^^^^^^^^
  File "aiohttp/_websocket/reader_c.py", line 118, in read
  File "aiohttp/_websocket/reader_c.py", line 115, in aiohttp._websocket.reader_c.WebSocketDataQueue.read
asyncio.exceptions.CancelledError
2025-10-19 17:33:54,038 - asyncio - ERROR - Exception in callback Future.race.<locals>.callback(<Task cancell...tasks.py:435>>) at /home/ar1ess/projects/crypto/.venv/lib/python3.12/site-packages/ccxt/async_support/base/ws/future.py:22
handle: <Handle Future.race.<locals>.callback(<Task cancell...tasks.py:435>>) at /home/ar1ess/projects/crypto/.venv/lib/python3.12/site-packages/ccxt/async_support/base/ws/future.py:22>
Traceback (most recent call last):
  File "/usr/lib/python3.12/asyncio/runners.py", line 118, in run
    return self._loop.run_until_complete(task)
           ^^^^^^^^^^^^^^^^^^^^^^^^^^^^^^^^^^^
  File "/usr/lib/python3.12/asyncio/base_events.py", line 687, in run_until_complete
    return future.result()
           ^^^^^^^^^^^^^^^
  File "/home/ar1ess/projects/crypto/brain/main.py", line 372, in main
    await analyst.start_update()
  File "/home/ar1ess/projects/crypto/brain/Core/Analyst.py", line 231, in start_update
    async for update_coin in self.scout.coin_update():
  File "/home/ar1ess/projects/crypto/brain/Core/scouts/ScoutDad.py", line 18, in coin_update
    answer = await self.queue.get()
             ^^^^^^^^^^^^^^^^^^^^^^
  File "/usr/lib/python3.12/asyncio/queues.py", line 158, in get
    await getter
asyncio.exceptions.CancelledError

During handling of the above exception, another exception occurred:

Traceback (most recent call last):
  File "/usr/lib/python3.12/asyncio/runners.py", line 194, in run
    return runner.run(main)
           ^^^^^^^^^^^^^^^^
  File "/usr/lib/python3.12/asyncio/runners.py", line 123, in run
    raise KeyboardInterrupt()
KeyboardInterrupt

During handling of the above exception, another exception occurred:

Traceback (most recent call last):
  File "/usr/lib/python3.12/asyncio/events.py", line 88, in _run
    self._context.run(self._callback, *self._args)
  File "/home/ar1ess/projects/crypto/.venv/lib/python3.12/site-packages/ccxt/async_support/base/ws/future.py", line 23, in callback
    complete, _ = done.result()
                  ^^^^^^^^^^^^^
  File "/usr/lib/python3.12/asyncio/tasks.py", line 464, in wait
    return await _wait(fs, timeout, return_when, loop)
           ^^^^^^^^^^^^^^^^^^^^^^^^^^^^^^^^^^^^^^^^^^^
  File "/usr/lib/python3.12/asyncio/tasks.py", line 550, in _wait
    await waiter
asyncio.exceptions.CancelledError
2025-10-19 17:33:54,039 - asyncio - ERROR - Exception in callback Client.receive_loop.<locals>.after_interrupt(<Task cancell...nt_ws.py:312>>) at /home/ar1ess/projects/crypto/.venv/lib/python3.12/site-packages/ccxt/async_support/base/ws/client.py:129
handle: <Handle Client.receive_loop.<locals>.after_interrupt(<Task cancell...nt_ws.py:312>>) at /home/ar1ess/projects/crypto/.venv/lib/python3.12/site-packages/ccxt/async_support/base/ws/client.py:129>
Traceback (most recent call last):
  File "/usr/lib/python3.12/asyncio/runners.py", line 118, in run
    return self._loop.run_until_complete(task)
           ^^^^^^^^^^^^^^^^^^^^^^^^^^^^^^^^^^^
  File "/usr/lib/python3.12/asyncio/base_events.py", line 687, in run_until_complete
    return future.result()
           ^^^^^^^^^^^^^^^
  File "/home/ar1ess/projects/crypto/brain/main.py", line 372, in main
    await analyst.start_update()
  File "/home/ar1ess/projects/crypto/brain/Core/Analyst.py", line 231, in start_update
    async for update_coin in self.scout.coin_update():
  File "/home/ar1ess/projects/crypto/brain/Core/scouts/ScoutDad.py", line 18, in coin_update
    answer = await self.queue.get()
             ^^^^^^^^^^^^^^^^^^^^^^
  File "/usr/lib/python3.12/asyncio/queues.py", line 158, in get
    await getter
asyncio.exceptions.CancelledError

During handling of the above exception, another exception occurred:

Traceback (most recent call last):
  File "/usr/lib/python3.12/asyncio/runners.py", line 194, in run
    return runner.run(main)
           ^^^^^^^^^^^^^^^^
  File "/usr/lib/python3.12/asyncio/runners.py", line 123, in run
    raise KeyboardInterrupt()
KeyboardInterrupt

During handling of the above exception, another exception occurred:

Traceback (most recent call last):
  File "/usr/lib/python3.12/asyncio/events.py", line 88, in _run
    self._context.run(self._callback, *self._args)
  File "/home/ar1ess/projects/crypto/.venv/lib/python3.12/site-packages/ccxt/async_support/base/ws/client.py", line 130, in after_interrupt
    exception = resolved.exception()
                ^^^^^^^^^^^^^^^^^^^^
  File "/home/ar1ess/projects/crypto/.venv/lib/python3.12/site-packages/aiohttp/client_ws.py", line 336, in receive
    msg = await self._reader.read()
          ^^^^^^^^^^^^^^^^^^^^^^^^^
  File "aiohttp/_websocket/reader_c.py", line 118, in read
  File "aiohttp/_websocket/reader_c.py", line 115, in aiohttp._websocket.reader_c.WebSocketDataQueue.read
asyncio.exceptions.CancelledError
2025-10-19 17:33:54,039 - asyncio - ERROR - Exception in callback Future.race.<locals>.callback(<Task cancell...tasks.py:435>>) at /home/ar1ess/projects/crypto/.venv/lib/python3.12/site-packages/ccxt/async_support/base/ws/future.py:22
handle: <Handle Future.race.<locals>.callback(<Task cancell...tasks.py:435>>) at /home/ar1ess/projects/crypto/.venv/lib/python3.12/site-packages/ccxt/async_support/base/ws/future.py:22>
Traceback (most recent call last):
  File "/usr/lib/python3.12/asyncio/runners.py", line 118, in run
    return self._loop.run_until_complete(task)
           ^^^^^^^^^^^^^^^^^^^^^^^^^^^^^^^^^^^
  File "/usr/lib/python3.12/asyncio/base_events.py", line 687, in run_until_complete
    return future.result()
           ^^^^^^^^^^^^^^^
  File "/home/ar1ess/projects/crypto/brain/main.py", line 372, in main
    await analyst.start_update()
  File "/home/ar1ess/projects/crypto/brain/Core/Analyst.py", line 231, in start_update
    async for update_coin in self.scout.coin_update():
  File "/home/ar1ess/projects/crypto/brain/Core/scouts/ScoutDad.py", line 18, in coin_update
    answer = await self.queue.get()
             ^^^^^^^^^^^^^^^^^^^^^^
  File "/usr/lib/python3.12/asyncio/queues.py", line 158, in get
    await getter
asyncio.exceptions.CancelledError

During handling of the above exception, another exception occurred:

Traceback (most recent call last):
  File "/usr/lib/python3.12/asyncio/runners.py", line 194, in run
    return runner.run(main)
           ^^^^^^^^^^^^^^^^
  File "/usr/lib/python3.12/asyncio/runners.py", line 123, in run
    raise KeyboardInterrupt()
KeyboardInterrupt

During handling of the above exception, another exception occurred:

Traceback (most recent call last):
  File "/usr/lib/python3.12/asyncio/events.py", line 88, in _run
    self._context.run(self._callback, *self._args)
  File "/home/ar1ess/projects/crypto/.venv/lib/python3.12/site-packages/ccxt/async_support/base/ws/future.py", line 23, in callback
    complete, _ = done.result()
                  ^^^^^^^^^^^^^
  File "/usr/lib/python3.12/asyncio/tasks.py", line 464, in wait
    return await _wait(fs, timeout, return_when, loop)
           ^^^^^^^^^^^^^^^^^^^^^^^^^^^^^^^^^^^^^^^^^^^
  File "/usr/lib/python3.12/asyncio/tasks.py", line 550, in _wait
    await waiter
asyncio.exceptions.CancelledError
2025-10-19 17:33:54,040 - asyncio - ERROR - Exception in callback Future.race.<locals>.callback(<Task cancell...tasks.py:435>>) at /home/ar1ess/projects/crypto/.venv/lib/python3.12/site-packages/ccxt/async_support/base/ws/future.py:22
handle: <Handle Future.race.<locals>.callback(<Task cancell...tasks.py:435>>) at /home/ar1ess/projects/crypto/.venv/lib/python3.12/site-packages/ccxt/async_support/base/ws/future.py:22>
Traceback (most recent call last):
  File "/usr/lib/python3.12/asyncio/runners.py", line 118, in run
    return self._loop.run_until_complete(task)
           ^^^^^^^^^^^^^^^^^^^^^^^^^^^^^^^^^^^
  File "/usr/lib/python3.12/asyncio/base_events.py", line 687, in run_until_complete
    return future.result()
           ^^^^^^^^^^^^^^^
  File "/home/ar1ess/projects/crypto/brain/main.py", line 372, in main
    await analyst.start_update()
  File "/home/ar1ess/projects/crypto/brain/Core/Analyst.py", line 231, in start_update
    async for update_coin in self.scout.coin_update():
  File "/home/ar1ess/projects/crypto/brain/Core/scouts/ScoutDad.py", line 18, in coin_update
    answer = await self.queue.get()
             ^^^^^^^^^^^^^^^^^^^^^^
  File "/usr/lib/python3.12/asyncio/queues.py", line 158, in get
    await getter
asyncio.exceptions.CancelledError

During handling of the above exception, another exception occurred:

Traceback (most recent call last):
  File "/usr/lib/python3.12/asyncio/runners.py", line 194, in run
    return runner.run(main)
           ^^^^^^^^^^^^^^^^
  File "/usr/lib/python3.12/asyncio/runners.py", line 123, in run
    raise KeyboardInterrupt()
KeyboardInterrupt

During handling of the above exception, another exception occurred:

Traceback (most recent call last):
  File "/usr/lib/python3.12/asyncio/events.py", line 88, in _run
    self._context.run(self._callback, *self._args)
  File "/home/ar1ess/projects/crypto/.venv/lib/python3.12/site-packages/ccxt/async_support/base/ws/future.py", line 23, in callback
    complete, _ = done.result()
                  ^^^^^^^^^^^^^
  File "/usr/lib/python3.12/asyncio/tasks.py", line 464, in wait
    return await _wait(fs, timeout, return_when, loop)
           ^^^^^^^^^^^^^^^^^^^^^^^^^^^^^^^^^^^^^^^^^^^
  File "/usr/lib/python3.12/asyncio/tasks.py", line 550, in _wait
    await waiter
asyncio.exceptions.CancelledError
2025-10-19 17:33:54,040 - asyncio - ERROR - Exception in callback Client.receive_loop.<locals>.after_interrupt(<Task cancell...nt_ws.py:312>>) at /home/ar1ess/projects/crypto/.venv/lib/python3.12/site-packages/ccxt/async_support/base/ws/client.py:129
handle: <Handle Client.receive_loop.<locals>.after_interrupt(<Task cancell...nt_ws.py:312>>) at /home/ar1ess/projects/crypto/.venv/lib/python3.12/site-packages/ccxt/async_support/base/ws/client.py:129>
Traceback (most recent call last):
  File "/usr/lib/python3.12/asyncio/runners.py", line 118, in run
    return self._loop.run_until_complete(task)
           ^^^^^^^^^^^^^^^^^^^^^^^^^^^^^^^^^^^
  File "/usr/lib/python3.12/asyncio/base_events.py", line 687, in run_until_complete
    return future.result()
           ^^^^^^^^^^^^^^^
  File "/home/ar1ess/projects/crypto/brain/main.py", line 372, in main
    await analyst.start_update()
  File "/home/ar1ess/projects/crypto/brain/Core/Analyst.py", line 231, in start_update
    async for update_coin in self.scout.coin_update():
  File "/home/ar1ess/projects/crypto/brain/Core/scouts/ScoutDad.py", line 18, in coin_update
    answer = await self.queue.get()
             ^^^^^^^^^^^^^^^^^^^^^^
  File "/usr/lib/python3.12/asyncio/queues.py", line 158, in get
    await getter
asyncio.exceptions.CancelledError

During handling of the above exception, another exception occurred:

Traceback (most recent call last):
  File "/usr/lib/python3.12/asyncio/runners.py", line 194, in run
    return runner.run(main)
           ^^^^^^^^^^^^^^^^
  File "/usr/lib/python3.12/asyncio/runners.py", line 123, in run
    raise KeyboardInterrupt()
KeyboardInterrupt

During handling of the above exception, another exception occurred:

Traceback (most recent call last):
  File "/usr/lib/python3.12/asyncio/events.py", line 88, in _run
    self._context.run(self._callback, *self._args)
  File "/home/ar1ess/projects/crypto/.venv/lib/python3.12/site-packages/ccxt/async_support/base/ws/client.py", line 130, in after_interrupt
    exception = resolved.exception()
                ^^^^^^^^^^^^^^^^^^^^
  File "/home/ar1ess/projects/crypto/.venv/lib/python3.12/site-packages/aiohttp/client_ws.py", line 336, in receive
    msg = await self._reader.read()
          ^^^^^^^^^^^^^^^^^^^^^^^^^
  File "aiohttp/_websocket/reader_c.py", line 118, in read
  File "aiohttp/_websocket/reader_c.py", line 115, in aiohttp._websocket.reader_c.WebSocketDataQueue.read
asyncio.exceptions.CancelledError
2025-10-19 17:33:54,041 - asyncio - ERROR - Exception in callback Future.race.<locals>.callback(<Task cancell...tasks.py:435>>) at /home/ar1ess/projects/crypto/.venv/lib/python3.12/site-packages/ccxt/async_support/base/ws/future.py:22
handle: <Handle Future.race.<locals>.callback(<Task cancell...tasks.py:435>>) at /home/ar1ess/projects/crypto/.venv/lib/python3.12/site-packages/ccxt/async_support/base/ws/future.py:22>
Traceback (most recent call last):
  File "/usr/lib/python3.12/asyncio/runners.py", line 118, in run
    return self._loop.run_until_complete(task)
           ^^^^^^^^^^^^^^^^^^^^^^^^^^^^^^^^^^^
  File "/usr/lib/python3.12/asyncio/base_events.py", line 687, in run_until_complete
    return future.result()
           ^^^^^^^^^^^^^^^
  File "/home/ar1ess/projects/crypto/brain/main.py", line 372, in main
    await analyst.start_update()
  File "/home/ar1ess/projects/crypto/brain/Core/Analyst.py", line 231, in start_update
    async for update_coin in self.scout.coin_update():
  File "/home/ar1ess/projects/crypto/brain/Core/scouts/ScoutDad.py", line 18, in coin_update
    answer = await self.queue.get()
             ^^^^^^^^^^^^^^^^^^^^^^
  File "/usr/lib/python3.12/asyncio/queues.py", line 158, in get
    await getter
asyncio.exceptions.CancelledError

During handling of the above exception, another exception occurred:

Traceback (most recent call last):
  File "/usr/lib/python3.12/asyncio/runners.py", line 194, in run
    return runner.run(main)
           ^^^^^^^^^^^^^^^^
  File "/usr/lib/python3.12/asyncio/runners.py", line 123, in run
    raise KeyboardInterrupt()
KeyboardInterrupt

During handling of the above exception, another exception occurred:

Traceback (most recent call last):
  File "/usr/lib/python3.12/asyncio/events.py", line 88, in _run
    self._context.run(self._callback, *self._args)
  File "/home/ar1ess/projects/crypto/.venv/lib/python3.12/site-packages/ccxt/async_support/base/ws/future.py", line 23, in callback
    complete, _ = done.result()
                  ^^^^^^^^^^^^^
  File "/usr/lib/python3.12/asyncio/tasks.py", line 464, in wait
    return await _wait(fs, timeout, return_when, loop)
           ^^^^^^^^^^^^^^^^^^^^^^^^^^^^^^^^^^^^^^^^^^^
  File "/usr/lib/python3.12/asyncio/tasks.py", line 550, in _wait
    await waiter
asyncio.exceptions.CancelledError
2025-10-19 17:33:54,041 - asyncio - ERROR - Exception in callback Client.receive_loop.<locals>.after_interrupt(<Task cancell...nt_ws.py:312>>) at /home/ar1ess/projects/crypto/.venv/lib/python3.12/site-packages/ccxt/async_support/base/ws/client.py:129
handle: <Handle Client.receive_loop.<locals>.after_interrupt(<Task cancell...nt_ws.py:312>>) at /home/ar1ess/projects/crypto/.venv/lib/python3.12/site-packages/ccxt/async_support/base/ws/client.py:129>
Traceback (most recent call last):
  File "/usr/lib/python3.12/asyncio/runners.py", line 118, in run
    return self._loop.run_until_complete(task)
           ^^^^^^^^^^^^^^^^^^^^^^^^^^^^^^^^^^^
  File "/usr/lib/python3.12/asyncio/base_events.py", line 687, in run_until_complete
    return future.result()
           ^^^^^^^^^^^^^^^
  File "/home/ar1ess/projects/crypto/brain/main.py", line 372, in main
    await analyst.start_update()
  File "/home/ar1ess/projects/crypto/brain/Core/Analyst.py", line 231, in start_update
    async for update_coin in self.scout.coin_update():
  File "/home/ar1ess/projects/crypto/brain/Core/scouts/ScoutDad.py", line 18, in coin_update
    answer = await self.queue.get()
             ^^^^^^^^^^^^^^^^^^^^^^
  File "/usr/lib/python3.12/asyncio/queues.py", line 158, in get
    await getter
asyncio.exceptions.CancelledError

During handling of the above exception, another exception occurred:

Traceback (most recent call last):
  File "/usr/lib/python3.12/asyncio/runners.py", line 194, in run
    return runner.run(main)
           ^^^^^^^^^^^^^^^^
  File "/usr/lib/python3.12/asyncio/runners.py", line 123, in run
    raise KeyboardInterrupt()
KeyboardInterrupt

During handling of the above exception, another exception occurred:

Traceback (most recent call last):
  File "/usr/lib/python3.12/asyncio/events.py", line 88, in _run
    self._context.run(self._callback, *self._args)
  File "/home/ar1ess/projects/crypto/.venv/lib/python3.12/site-packages/ccxt/async_support/base/ws/client.py", line 130, in after_interrupt
    exception = resolved.exception()
                ^^^^^^^^^^^^^^^^^^^^
  File "/home/ar1ess/projects/crypto/.venv/lib/python3.12/site-packages/aiohttp/client_ws.py", line 336, in receive
    msg = await self._reader.read()
          ^^^^^^^^^^^^^^^^^^^^^^^^^
  File "aiohttp/_websocket/reader_c.py", line 118, in read
  File "aiohttp/_websocket/reader_c.py", line 115, in aiohttp._websocket.reader_c.WebSocketDataQueue.read
asyncio.exceptions.CancelledError
2025-10-19 17:33:54,042 - asyncio - ERROR - Exception in callback Future.race.<locals>.callback(<Task cancell...tasks.py:435>>) at /home/ar1ess/projects/crypto/.venv/lib/python3.12/site-packages/ccxt/async_support/base/ws/future.py:22
handle: <Handle Future.race.<locals>.callback(<Task cancell...tasks.py:435>>) at /home/ar1ess/projects/crypto/.venv/lib/python3.12/site-packages/ccxt/async_support/base/ws/future.py:22>
Traceback (most recent call last):
  File "/usr/lib/python3.12/asyncio/runners.py", line 118, in run
    return self._loop.run_until_complete(task)
           ^^^^^^^^^^^^^^^^^^^^^^^^^^^^^^^^^^^
  File "/usr/lib/python3.12/asyncio/base_events.py", line 687, in run_until_complete
    return future.result()
           ^^^^^^^^^^^^^^^
  File "/home/ar1ess/projects/crypto/brain/main.py", line 372, in main
    await analyst.start_update()
  File "/home/ar1ess/projects/crypto/brain/Core/Analyst.py", line 231, in start_update
    async for update_coin in self.scout.coin_update():
  File "/home/ar1ess/projects/crypto/brain/Core/scouts/ScoutDad.py", line 18, in coin_update
    answer = await self.queue.get()
             ^^^^^^^^^^^^^^^^^^^^^^
  File "/usr/lib/python3.12/asyncio/queues.py", line 158, in get
    await getter
asyncio.exceptions.CancelledError

During handling of the above exception, another exception occurred:

Traceback (most recent call last):
  File "/usr/lib/python3.12/asyncio/runners.py", line 194, in run
    return runner.run(main)
           ^^^^^^^^^^^^^^^^
  File "/usr/lib/python3.12/asyncio/runners.py", line 123, in run
    raise KeyboardInterrupt()
KeyboardInterrupt

During handling of the above exception, another exception occurred:

Traceback (most recent call last):
  File "/usr/lib/python3.12/asyncio/events.py", line 88, in _run
    self._context.run(self._callback, *self._args)
  File "/home/ar1ess/projects/crypto/.venv/lib/python3.12/site-packages/ccxt/async_support/base/ws/future.py", line 23, in callback
    complete, _ = done.result()
                  ^^^^^^^^^^^^^
  File "/usr/lib/python3.12/asyncio/tasks.py", line 464, in wait
    return await _wait(fs, timeout, return_when, loop)
           ^^^^^^^^^^^^^^^^^^^^^^^^^^^^^^^^^^^^^^^^^^^
  File "/usr/lib/python3.12/asyncio/tasks.py", line 550, in _wait
    await waiter
asyncio.exceptions.CancelledError
2025-10-19 17:33:54,042 - asyncio - ERROR - Exception in callback Client.receive_loop.<locals>.after_interrupt(<Task cancell...nt_ws.py:312>>) at /home/ar1ess/projects/crypto/.venv/lib/python3.12/site-packages/ccxt/async_support/base/ws/client.py:129
handle: <Handle Client.receive_loop.<locals>.after_interrupt(<Task cancell...nt_ws.py:312>>) at /home/ar1ess/projects/crypto/.venv/lib/python3.12/site-packages/ccxt/async_support/base/ws/client.py:129>
Traceback (most recent call last):
  File "/usr/lib/python3.12/asyncio/runners.py", line 118, in run
    return self._loop.run_until_complete(task)
           ^^^^^^^^^^^^^^^^^^^^^^^^^^^^^^^^^^^
  File "/usr/lib/python3.12/asyncio/base_events.py", line 687, in run_until_complete
    return future.result()
           ^^^^^^^^^^^^^^^
  File "/home/ar1ess/projects/crypto/brain/main.py", line 372, in main
    await analyst.start_update()
  File "/home/ar1ess/projects/crypto/brain/Core/Analyst.py", line 231, in start_update
    async for update_coin in self.scout.coin_update():
  File "/home/ar1ess/projects/crypto/brain/Core/scouts/ScoutDad.py", line 18, in coin_update
    answer = await self.queue.get()
             ^^^^^^^^^^^^^^^^^^^^^^
  File "/usr/lib/python3.12/asyncio/queues.py", line 158, in get
    await getter
asyncio.exceptions.CancelledError

During handling of the above exception, another exception occurred:

Traceback (most recent call last):
  File "/usr/lib/python3.12/asyncio/runners.py", line 194, in run
    return runner.run(main)
           ^^^^^^^^^^^^^^^^
  File "/usr/lib/python3.12/asyncio/runners.py", line 123, in run
    raise KeyboardInterrupt()
KeyboardInterrupt

During handling of the above exception, another exception occurred:

Traceback (most recent call last):
  File "/usr/lib/python3.12/asyncio/events.py", line 88, in _run
    self._context.run(self._callback, *self._args)
  File "/home/ar1ess/projects/crypto/.venv/lib/python3.12/site-packages/ccxt/async_support/base/ws/client.py", line 130, in after_interrupt
    exception = resolved.exception()
                ^^^^^^^^^^^^^^^^^^^^
  File "/home/ar1ess/projects/crypto/.venv/lib/python3.12/site-packages/aiohttp/client_ws.py", line 336, in receive
    msg = await self._reader.read()
          ^^^^^^^^^^^^^^^^^^^^^^^^^
  File "aiohttp/_websocket/reader_c.py", line 118, in read
  File "aiohttp/_websocket/reader_c.py", line 115, in aiohttp._websocket.reader_c.WebSocketDataQueue.read
asyncio.exceptions.CancelledError
2025-10-19 17:35:57,422 - asyncio - ERROR - Exception in callback Client.receive_loop.<locals>.after_interrupt(<Task cancell...nt_ws.py:312>>) at /home/ar1ess/projects/crypto/.venv/lib/python3.12/site-packages/ccxt/async_support/base/ws/client.py:129
handle: <Handle Client.receive_loop.<locals>.after_interrupt(<Task cancell...nt_ws.py:312>>) at /home/ar1ess/projects/crypto/.venv/lib/python3.12/site-packages/ccxt/async_support/base/ws/client.py:129>
Traceback (most recent call last):
  File "/usr/lib/python3.12/asyncio/runners.py", line 118, in run
    return self._loop.run_until_complete(task)
           ^^^^^^^^^^^^^^^^^^^^^^^^^^^^^^^^^^^
  File "/usr/lib/python3.12/asyncio/base_events.py", line 687, in run_until_complete
    return future.result()
           ^^^^^^^^^^^^^^^
  File "/home/ar1ess/projects/crypto/brain/main.py", line 376, in main
    await asyncio.wait([update_task, monitor_task],
  File "/usr/lib/python3.12/asyncio/tasks.py", line 464, in wait
    return await _wait(fs, timeout, return_when, loop)
           ^^^^^^^^^^^^^^^^^^^^^^^^^^^^^^^^^^^^^^^^^^^
  File "/usr/lib/python3.12/asyncio/tasks.py", line 550, in _wait
    await waiter
asyncio.exceptions.CancelledError

During handling of the above exception, another exception occurred:

Traceback (most recent call last):
  File "/usr/lib/python3.12/asyncio/runners.py", line 194, in run
    return runner.run(main)
           ^^^^^^^^^^^^^^^^
  File "/usr/lib/python3.12/asyncio/runners.py", line 123, in run
    raise KeyboardInterrupt()
KeyboardInterrupt

During handling of the above exception, another exception occurred:

Traceback (most recent call last):
  File "/usr/lib/python3.12/asyncio/events.py", line 88, in _run
    self._context.run(self._callback, *self._args)
  File "/home/ar1ess/projects/crypto/.venv/lib/python3.12/site-packages/ccxt/async_support/base/ws/client.py", line 130, in after_interrupt
    exception = resolved.exception()
                ^^^^^^^^^^^^^^^^^^^^
  File "/home/ar1ess/projects/crypto/.venv/lib/python3.12/site-packages/aiohttp/client_ws.py", line 336, in receive
    msg = await self._reader.read()
          ^^^^^^^^^^^^^^^^^^^^^^^^^
  File "aiohttp/_websocket/reader_c.py", line 118, in read
  File "aiohttp/_websocket/reader_c.py", line 115, in aiohttp._websocket.reader_c.WebSocketDataQueue.read
asyncio.exceptions.CancelledError
2025-10-19 17:35:57,425 - asyncio - ERROR - Exception in callback Future.race.<locals>.callback(<Task cancell...tasks.py:435>>) at /home/ar1ess/projects/crypto/.venv/lib/python3.12/site-packages/ccxt/async_support/base/ws/future.py:22
handle: <Handle Future.race.<locals>.callback(<Task cancell...tasks.py:435>>) at /home/ar1ess/projects/crypto/.venv/lib/python3.12/site-packages/ccxt/async_support/base/ws/future.py:22>
Traceback (most recent call last):
  File "/usr/lib/python3.12/asyncio/runners.py", line 118, in run
    return self._loop.run_until_complete(task)
           ^^^^^^^^^^^^^^^^^^^^^^^^^^^^^^^^^^^
  File "/usr/lib/python3.12/asyncio/base_events.py", line 687, in run_until_complete
    return future.result()
           ^^^^^^^^^^^^^^^
  File "/home/ar1ess/projects/crypto/brain/main.py", line 376, in main
    await asyncio.wait([update_task, monitor_task],
  File "/usr/lib/python3.12/asyncio/tasks.py", line 464, in wait
    return await _wait(fs, timeout, return_when, loop)
           ^^^^^^^^^^^^^^^^^^^^^^^^^^^^^^^^^^^^^^^^^^^
  File "/usr/lib/python3.12/asyncio/tasks.py", line 550, in _wait
    await waiter
asyncio.exceptions.CancelledError

During handling of the above exception, another exception occurred:

Traceback (most recent call last):
  File "/usr/lib/python3.12/asyncio/runners.py", line 194, in run
    return runner.run(main)
           ^^^^^^^^^^^^^^^^
  File "/usr/lib/python3.12/asyncio/runners.py", line 123, in run
    raise KeyboardInterrupt()
KeyboardInterrupt

During handling of the above exception, another exception occurred:

Traceback (most recent call last):
  File "/usr/lib/python3.12/asyncio/events.py", line 88, in _run
    self._context.run(self._callback, *self._args)
  File "/home/ar1ess/projects/crypto/.venv/lib/python3.12/site-packages/ccxt/async_support/base/ws/future.py", line 23, in callback
    complete, _ = done.result()
                  ^^^^^^^^^^^^^
  File "/usr/lib/python3.12/asyncio/tasks.py", line 464, in wait
    return await _wait(fs, timeout, return_when, loop)
           ^^^^^^^^^^^^^^^^^^^^^^^^^^^^^^^^^^^^^^^^^^^
  File "/usr/lib/python3.12/asyncio/tasks.py", line 550, in _wait
    await waiter
asyncio.exceptions.CancelledError
2025-10-19 17:35:57,426 - asyncio - ERROR - Exception in callback Client.receive_loop.<locals>.after_interrupt(<Task cancell...nt_ws.py:312>>) at /home/ar1ess/projects/crypto/.venv/lib/python3.12/site-packages/ccxt/async_support/base/ws/client.py:129
handle: <Handle Client.receive_loop.<locals>.after_interrupt(<Task cancell...nt_ws.py:312>>) at /home/ar1ess/projects/crypto/.venv/lib/python3.12/site-packages/ccxt/async_support/base/ws/client.py:129>
Traceback (most recent call last):
  File "/usr/lib/python3.12/asyncio/runners.py", line 118, in run
    return self._loop.run_until_complete(task)
           ^^^^^^^^^^^^^^^^^^^^^^^^^^^^^^^^^^^
  File "/usr/lib/python3.12/asyncio/base_events.py", line 687, in run_until_complete
    return future.result()
           ^^^^^^^^^^^^^^^
  File "/home/ar1ess/projects/crypto/brain/main.py", line 376, in main
    await asyncio.wait([update_task, monitor_task],
  File "/usr/lib/python3.12/asyncio/tasks.py", line 464, in wait
    return await _wait(fs, timeout, return_when, loop)
           ^^^^^^^^^^^^^^^^^^^^^^^^^^^^^^^^^^^^^^^^^^^
  File "/usr/lib/python3.12/asyncio/tasks.py", line 550, in _wait
    await waiter
asyncio.exceptions.CancelledError

During handling of the above exception, another exception occurred:

Traceback (most recent call last):
  File "/usr/lib/python3.12/asyncio/runners.py", line 194, in run
    return runner.run(main)
           ^^^^^^^^^^^^^^^^
  File "/usr/lib/python3.12/asyncio/runners.py", line 123, in run
    raise KeyboardInterrupt()
KeyboardInterrupt

During handling of the above exception, another exception occurred:

Traceback (most recent call last):
  File "/usr/lib/python3.12/asyncio/events.py", line 88, in _run
    self._context.run(self._callback, *self._args)
  File "/home/ar1ess/projects/crypto/.venv/lib/python3.12/site-packages/ccxt/async_support/base/ws/client.py", line 130, in after_interrupt
    exception = resolved.exception()
                ^^^^^^^^^^^^^^^^^^^^
  File "/home/ar1ess/projects/crypto/.venv/lib/python3.12/site-packages/aiohttp/client_ws.py", line 336, in receive
    msg = await self._reader.read()
          ^^^^^^^^^^^^^^^^^^^^^^^^^
  File "aiohttp/_websocket/reader_c.py", line 118, in read
  File "aiohttp/_websocket/reader_c.py", line 115, in aiohttp._websocket.reader_c.WebSocketDataQueue.read
asyncio.exceptions.CancelledError
2025-10-19 17:35:57,427 - asyncio - ERROR - Exception in callback Client.receive_loop.<locals>.after_interrupt(<Task cancell...nt_ws.py:312>>) at /home/ar1ess/projects/crypto/.venv/lib/python3.12/site-packages/ccxt/async_support/base/ws/client.py:129
handle: <Handle Client.receive_loop.<locals>.after_interrupt(<Task cancell...nt_ws.py:312>>) at /home/ar1ess/projects/crypto/.venv/lib/python3.12/site-packages/ccxt/async_support/base/ws/client.py:129>
Traceback (most recent call last):
  File "/usr/lib/python3.12/asyncio/runners.py", line 118, in run
    return self._loop.run_until_complete(task)
           ^^^^^^^^^^^^^^^^^^^^^^^^^^^^^^^^^^^
  File "/usr/lib/python3.12/asyncio/base_events.py", line 687, in run_until_complete
    return future.result()
           ^^^^^^^^^^^^^^^
  File "/home/ar1ess/projects/crypto/brain/main.py", line 376, in main
    await asyncio.wait([update_task, monitor_task],
  File "/usr/lib/python3.12/asyncio/tasks.py", line 464, in wait
    return await _wait(fs, timeout, return_when, loop)
           ^^^^^^^^^^^^^^^^^^^^^^^^^^^^^^^^^^^^^^^^^^^
  File "/usr/lib/python3.12/asyncio/tasks.py", line 550, in _wait
    await waiter
asyncio.exceptions.CancelledError

During handling of the above exception, another exception occurred:

Traceback (most recent call last):
  File "/usr/lib/python3.12/asyncio/runners.py", line 194, in run
    return runner.run(main)
           ^^^^^^^^^^^^^^^^
  File "/usr/lib/python3.12/asyncio/runners.py", line 123, in run
    raise KeyboardInterrupt()
KeyboardInterrupt

During handling of the above exception, another exception occurred:

Traceback (most recent call last):
  File "/usr/lib/python3.12/asyncio/events.py", line 88, in _run
    self._context.run(self._callback, *self._args)
  File "/home/ar1ess/projects/crypto/.venv/lib/python3.12/site-packages/ccxt/async_support/base/ws/client.py", line 130, in after_interrupt
    exception = resolved.exception()
                ^^^^^^^^^^^^^^^^^^^^
  File "/home/ar1ess/projects/crypto/.venv/lib/python3.12/site-packages/aiohttp/client_ws.py", line 336, in receive
    msg = await self._reader.read()
          ^^^^^^^^^^^^^^^^^^^^^^^^^
  File "aiohttp/_websocket/reader_c.py", line 118, in read
  File "aiohttp/_websocket/reader_c.py", line 115, in aiohttp._websocket.reader_c.WebSocketDataQueue.read
asyncio.exceptions.CancelledError
2025-10-19 17:35:57,428 - asyncio - ERROR - Exception in callback Client.receive_loop.<locals>.after_interrupt(<Task cancell...nt_ws.py:312>>) at /home/ar1ess/projects/crypto/.venv/lib/python3.12/site-packages/ccxt/async_support/base/ws/client.py:129
handle: <Handle Client.receive_loop.<locals>.after_interrupt(<Task cancell...nt_ws.py:312>>) at /home/ar1ess/projects/crypto/.venv/lib/python3.12/site-packages/ccxt/async_support/base/ws/client.py:129>
Traceback (most recent call last):
  File "/usr/lib/python3.12/asyncio/runners.py", line 118, in run
    return self._loop.run_until_complete(task)
           ^^^^^^^^^^^^^^^^^^^^^^^^^^^^^^^^^^^
  File "/usr/lib/python3.12/asyncio/base_events.py", line 687, in run_until_complete
    return future.result()
           ^^^^^^^^^^^^^^^
  File "/home/ar1ess/projects/crypto/brain/main.py", line 376, in main
    await asyncio.wait([update_task, monitor_task],
  File "/usr/lib/python3.12/asyncio/tasks.py", line 464, in wait
    return await _wait(fs, timeout, return_when, loop)
           ^^^^^^^^^^^^^^^^^^^^^^^^^^^^^^^^^^^^^^^^^^^
  File "/usr/lib/python3.12/asyncio/tasks.py", line 550, in _wait
    await waiter
asyncio.exceptions.CancelledError

During handling of the above exception, another exception occurred:

Traceback (most recent call last):
  File "/usr/lib/python3.12/asyncio/runners.py", line 194, in run
    return runner.run(main)
           ^^^^^^^^^^^^^^^^
  File "/usr/lib/python3.12/asyncio/runners.py", line 123, in run
    raise KeyboardInterrupt()
KeyboardInterrupt

During handling of the above exception, another exception occurred:

Traceback (most recent call last):
  File "/usr/lib/python3.12/asyncio/events.py", line 88, in _run
    self._context.run(self._callback, *self._args)
  File "/home/ar1ess/projects/crypto/.venv/lib/python3.12/site-packages/ccxt/async_support/base/ws/client.py", line 130, in after_interrupt
    exception = resolved.exception()
                ^^^^^^^^^^^^^^^^^^^^
  File "/home/ar1ess/projects/crypto/.venv/lib/python3.12/site-packages/aiohttp/client_ws.py", line 336, in receive
    msg = await self._reader.read()
          ^^^^^^^^^^^^^^^^^^^^^^^^^
  File "aiohttp/_websocket/reader_c.py", line 118, in read
  File "aiohttp/_websocket/reader_c.py", line 115, in aiohttp._websocket.reader_c.WebSocketDataQueue.read
asyncio.exceptions.CancelledError
2025-10-19 17:35:57,428 - asyncio - ERROR - Exception in callback Future.race.<locals>.callback(<Task cancell...tasks.py:435>>) at /home/ar1ess/projects/crypto/.venv/lib/python3.12/site-packages/ccxt/async_support/base/ws/future.py:22
handle: <Handle Future.race.<locals>.callback(<Task cancell...tasks.py:435>>) at /home/ar1ess/projects/crypto/.venv/lib/python3.12/site-packages/ccxt/async_support/base/ws/future.py:22>
Traceback (most recent call last):
  File "/usr/lib/python3.12/asyncio/runners.py", line 118, in run
    return self._loop.run_until_complete(task)
           ^^^^^^^^^^^^^^^^^^^^^^^^^^^^^^^^^^^
  File "/usr/lib/python3.12/asyncio/base_events.py", line 687, in run_until_complete
    return future.result()
           ^^^^^^^^^^^^^^^
  File "/home/ar1ess/projects/crypto/brain/main.py", line 376, in main
    await asyncio.wait([update_task, monitor_task],
  File "/usr/lib/python3.12/asyncio/tasks.py", line 464, in wait
    return await _wait(fs, timeout, return_when, loop)
           ^^^^^^^^^^^^^^^^^^^^^^^^^^^^^^^^^^^^^^^^^^^
  File "/usr/lib/python3.12/asyncio/tasks.py", line 550, in _wait
    await waiter
asyncio.exceptions.CancelledError

During handling of the above exception, another exception occurred:

Traceback (most recent call last):
  File "/usr/lib/python3.12/asyncio/runners.py", line 194, in run
    return runner.run(main)
           ^^^^^^^^^^^^^^^^
  File "/usr/lib/python3.12/asyncio/runners.py", line 123, in run
    raise KeyboardInterrupt()
KeyboardInterrupt

During handling of the above exception, another exception occurred:

Traceback (most recent call last):
  File "/usr/lib/python3.12/asyncio/events.py", line 88, in _run
    self._context.run(self._callback, *self._args)
  File "/home/ar1ess/projects/crypto/.venv/lib/python3.12/site-packages/ccxt/async_support/base/ws/future.py", line 23, in callback
    complete, _ = done.result()
                  ^^^^^^^^^^^^^
  File "/usr/lib/python3.12/asyncio/tasks.py", line 464, in wait
    return await _wait(fs, timeout, return_when, loop)
           ^^^^^^^^^^^^^^^^^^^^^^^^^^^^^^^^^^^^^^^^^^^
  File "/usr/lib/python3.12/asyncio/tasks.py", line 550, in _wait
    await waiter
asyncio.exceptions.CancelledError
2025-10-19 17:35:57,429 - asyncio - ERROR - Exception in callback Future.race.<locals>.callback(<Task cancell...tasks.py:435>>) at /home/ar1ess/projects/crypto/.venv/lib/python3.12/site-packages/ccxt/async_support/base/ws/future.py:22
handle: <Handle Future.race.<locals>.callback(<Task cancell...tasks.py:435>>) at /home/ar1ess/projects/crypto/.venv/lib/python3.12/site-packages/ccxt/async_support/base/ws/future.py:22>
Traceback (most recent call last):
  File "/usr/lib/python3.12/asyncio/runners.py", line 118, in run
    return self._loop.run_until_complete(task)
           ^^^^^^^^^^^^^^^^^^^^^^^^^^^^^^^^^^^
  File "/usr/lib/python3.12/asyncio/base_events.py", line 687, in run_until_complete
    return future.result()
           ^^^^^^^^^^^^^^^
  File "/home/ar1ess/projects/crypto/brain/main.py", line 376, in main
    await asyncio.wait([update_task, monitor_task],
  File "/usr/lib/python3.12/asyncio/tasks.py", line 464, in wait
    return await _wait(fs, timeout, return_when, loop)
           ^^^^^^^^^^^^^^^^^^^^^^^^^^^^^^^^^^^^^^^^^^^
  File "/usr/lib/python3.12/asyncio/tasks.py", line 550, in _wait
    await waiter
asyncio.exceptions.CancelledError

During handling of the above exception, another exception occurred:

Traceback (most recent call last):
  File "/usr/lib/python3.12/asyncio/runners.py", line 194, in run
    return runner.run(main)
           ^^^^^^^^^^^^^^^^
  File "/usr/lib/python3.12/asyncio/runners.py", line 123, in run
    raise KeyboardInterrupt()
KeyboardInterrupt

During handling of the above exception, another exception occurred:

Traceback (most recent call last):
  File "/usr/lib/python3.12/asyncio/events.py", line 88, in _run
    self._context.run(self._callback, *self._args)
  File "/home/ar1ess/projects/crypto/.venv/lib/python3.12/site-packages/ccxt/async_support/base/ws/future.py", line 23, in callback
    complete, _ = done.result()
                  ^^^^^^^^^^^^^
  File "/usr/lib/python3.12/asyncio/tasks.py", line 464, in wait
    return await _wait(fs, timeout, return_when, loop)
           ^^^^^^^^^^^^^^^^^^^^^^^^^^^^^^^^^^^^^^^^^^^
  File "/usr/lib/python3.12/asyncio/tasks.py", line 550, in _wait
    await waiter
asyncio.exceptions.CancelledError
2025-10-19 17:35:57,430 - asyncio - ERROR - Exception in callback Future.race.<locals>.callback(<Task cancell...tasks.py:435>>) at /home/ar1ess/projects/crypto/.venv/lib/python3.12/site-packages/ccxt/async_support/base/ws/future.py:22
handle: <Handle Future.race.<locals>.callback(<Task cancell...tasks.py:435>>) at /home/ar1ess/projects/crypto/.venv/lib/python3.12/site-packages/ccxt/async_support/base/ws/future.py:22>
Traceback (most recent call last):
  File "/usr/lib/python3.12/asyncio/runners.py", line 118, in run
    return self._loop.run_until_complete(task)
           ^^^^^^^^^^^^^^^^^^^^^^^^^^^^^^^^^^^
  File "/usr/lib/python3.12/asyncio/base_events.py", line 687, in run_until_complete
    return future.result()
           ^^^^^^^^^^^^^^^
  File "/home/ar1ess/projects/crypto/brain/main.py", line 376, in main
    await asyncio.wait([update_task, monitor_task],
  File "/usr/lib/python3.12/asyncio/tasks.py", line 464, in wait
    return await _wait(fs, timeout, return_when, loop)
           ^^^^^^^^^^^^^^^^^^^^^^^^^^^^^^^^^^^^^^^^^^^
  File "/usr/lib/python3.12/asyncio/tasks.py", line 550, in _wait
    await waiter
asyncio.exceptions.CancelledError

During handling of the above exception, another exception occurred:

Traceback (most recent call last):
  File "/usr/lib/python3.12/asyncio/runners.py", line 194, in run
    return runner.run(main)
           ^^^^^^^^^^^^^^^^
  File "/usr/lib/python3.12/asyncio/runners.py", line 123, in run
    raise KeyboardInterrupt()
KeyboardInterrupt

During handling of the above exception, another exception occurred:

Traceback (most recent call last):
  File "/usr/lib/python3.12/asyncio/events.py", line 88, in _run
    self._context.run(self._callback, *self._args)
  File "/home/ar1ess/projects/crypto/.venv/lib/python3.12/site-packages/ccxt/async_support/base/ws/future.py", line 23, in callback
    complete, _ = done.result()
                  ^^^^^^^^^^^^^
  File "/usr/lib/python3.12/asyncio/tasks.py", line 464, in wait
    return await _wait(fs, timeout, return_when, loop)
           ^^^^^^^^^^^^^^^^^^^^^^^^^^^^^^^^^^^^^^^^^^^
  File "/usr/lib/python3.12/asyncio/tasks.py", line 550, in _wait
    await waiter
asyncio.exceptions.CancelledError
2025-10-19 17:35:57,431 - asyncio - ERROR - Exception in callback Future.race.<locals>.callback(<Task cancell...tasks.py:435>>) at /home/ar1ess/projects/crypto/.venv/lib/python3.12/site-packages/ccxt/async_support/base/ws/future.py:22
handle: <Handle Future.race.<locals>.callback(<Task cancell...tasks.py:435>>) at /home/ar1ess/projects/crypto/.venv/lib/python3.12/site-packages/ccxt/async_support/base/ws/future.py:22>
Traceback (most recent call last):
  File "/usr/lib/python3.12/asyncio/runners.py", line 118, in run
    return self._loop.run_until_complete(task)
           ^^^^^^^^^^^^^^^^^^^^^^^^^^^^^^^^^^^
  File "/usr/lib/python3.12/asyncio/base_events.py", line 687, in run_until_complete
    return future.result()
           ^^^^^^^^^^^^^^^
  File "/home/ar1ess/projects/crypto/brain/main.py", line 376, in main
    await asyncio.wait([update_task, monitor_task],
  File "/usr/lib/python3.12/asyncio/tasks.py", line 464, in wait
    return await _wait(fs, timeout, return_when, loop)
           ^^^^^^^^^^^^^^^^^^^^^^^^^^^^^^^^^^^^^^^^^^^
  File "/usr/lib/python3.12/asyncio/tasks.py", line 550, in _wait
    await waiter
asyncio.exceptions.CancelledError

During handling of the above exception, another exception occurred:

Traceback (most recent call last):
  File "/usr/lib/python3.12/asyncio/runners.py", line 194, in run
    return runner.run(main)
           ^^^^^^^^^^^^^^^^
  File "/usr/lib/python3.12/asyncio/runners.py", line 123, in run
    raise KeyboardInterrupt()
KeyboardInterrupt

During handling of the above exception, another exception occurred:

Traceback (most recent call last):
  File "/usr/lib/python3.12/asyncio/events.py", line 88, in _run
    self._context.run(self._callback, *self._args)
  File "/home/ar1ess/projects/crypto/.venv/lib/python3.12/site-packages/ccxt/async_support/base/ws/future.py", line 23, in callback
    complete, _ = done.result()
                  ^^^^^^^^^^^^^
  File "/usr/lib/python3.12/asyncio/tasks.py", line 464, in wait
    return await _wait(fs, timeout, return_when, loop)
           ^^^^^^^^^^^^^^^^^^^^^^^^^^^^^^^^^^^^^^^^^^^
  File "/usr/lib/python3.12/asyncio/tasks.py", line 550, in _wait
    await waiter
asyncio.exceptions.CancelledError
2025-10-19 17:35:57,432 - asyncio - ERROR - Exception in callback Client.receive_loop.<locals>.after_interrupt(<Task cancell...nt_ws.py:312>>) at /home/ar1ess/projects/crypto/.venv/lib/python3.12/site-packages/ccxt/async_support/base/ws/client.py:129
handle: <Handle Client.receive_loop.<locals>.after_interrupt(<Task cancell...nt_ws.py:312>>) at /home/ar1ess/projects/crypto/.venv/lib/python3.12/site-packages/ccxt/async_support/base/ws/client.py:129>
Traceback (most recent call last):
  File "/usr/lib/python3.12/asyncio/runners.py", line 118, in run
    return self._loop.run_until_complete(task)
           ^^^^^^^^^^^^^^^^^^^^^^^^^^^^^^^^^^^
  File "/usr/lib/python3.12/asyncio/base_events.py", line 687, in run_until_complete
    return future.result()
           ^^^^^^^^^^^^^^^
  File "/home/ar1ess/projects/crypto/brain/main.py", line 376, in main
    await asyncio.wait([update_task, monitor_task],
  File "/usr/lib/python3.12/asyncio/tasks.py", line 464, in wait
    return await _wait(fs, timeout, return_when, loop)
           ^^^^^^^^^^^^^^^^^^^^^^^^^^^^^^^^^^^^^^^^^^^
  File "/usr/lib/python3.12/asyncio/tasks.py", line 550, in _wait
    await waiter
asyncio.exceptions.CancelledError

During handling of the above exception, another exception occurred:

Traceback (most recent call last):
  File "/usr/lib/python3.12/asyncio/runners.py", line 194, in run
    return runner.run(main)
           ^^^^^^^^^^^^^^^^
  File "/usr/lib/python3.12/asyncio/runners.py", line 123, in run
    raise KeyboardInterrupt()
KeyboardInterrupt

During handling of the above exception, another exception occurred:

Traceback (most recent call last):
  File "/usr/lib/python3.12/asyncio/events.py", line 88, in _run
    self._context.run(self._callback, *self._args)
  File "/home/ar1ess/projects/crypto/.venv/lib/python3.12/site-packages/ccxt/async_support/base/ws/client.py", line 130, in after_interrupt
    exception = resolved.exception()
                ^^^^^^^^^^^^^^^^^^^^
  File "/home/ar1ess/projects/crypto/.venv/lib/python3.12/site-packages/aiohttp/client_ws.py", line 336, in receive
    msg = await self._reader.read()
          ^^^^^^^^^^^^^^^^^^^^^^^^^
  File "aiohttp/_websocket/reader_c.py", line 118, in read
  File "aiohttp/_websocket/reader_c.py", line 115, in aiohttp._websocket.reader_c.WebSocketDataQueue.read
asyncio.exceptions.CancelledError
